Workbook

Sheet A Loose
A1: A — Loose Items (what you count on the shelf)
A2: Type in the amber columns only; grey columns work themselves out. Opening Qty is your starting count — everything after it comes from the Movements tab. Unit is a fixed list; Pcs per Pack only opens up on a unit that holds pieces (Box, Pack, Set, Bundle, Dozen, Roll). The three Sold columns say where the stock went: sold loose on its own, gone into a B item, or gone straight into a kit. Opening + Received - the three Sold columns + Adjusted = Stock in Hand.
A4: Code | B4: Item Name | C4: Unit | D4: Pcs per Pack | E4: Opening Qty | F4: Received | G4: Sold as A | H4: Sold as B | I4: Sold as C | J4: Adjusted | K4: STOCK IN HAND | L4: Notes
A5: WHT-BAL | B5: White Balloon | C5: Box | D5: 100 | E5: 1000 | F5: =IF($A5="","",SUMIFS(Movements!$D$5:$D$304,Movements!$C$5:$C$304,$A5,Movements!$B$5:$B$304,"Receive")) -> 500 | G5: =IF($A5="","",SUMIFS(Movements!$D$5:$D$304,Movements!$C$5:$C$304,$A5,Movements!$B$5:$B$304,"Sell")) -> 0 | H5: =IF($A5="","",SUMIFS(Recipes!$H$5:$H$104,Recipes!$C$5:$C$104,$A5,Recipes!$B$5:$B$104,"B")) -> 780 | I5: =IF($A5="","",SUMIFS(Recipes!$H$5:$H$104,Recipes!$C$5:$C$104,$A5,Recipes!$B$5:$B$104,"C")) -> 120 | J5: =IF($A5="","",SUMIFS(Movements!$D$5:$D$304,Movements!$C$5:$C$304,$A5,Movements!$B$5:$B$304,"Adjust")) -> -20 | K5: =IF($A5="","",$E5+$F5-$G5-$H5-$I5+$J5) -> 580 | L5: EXAMPLE ROWS - delete rows 5-9 and put your own items in
A6: GLD-FOIL-1 | B6: Gold Foil Number 1 | C6: Pcs | E6: 60 | F6: =IF($A6="","",SUMIFS(Movements!$D$5:$D$304,Movements!$C$5:$C$304,$A6,Movements!$B$5:$B$304,"Receive")) -> 0 | G6: =IF($A6="","",SUMIFS(Movements!$D$5:$D$304,Movements!$C$5:$C$304,$A6,Movements!$B$5:$B$304,"Sell")) -> 0 | H6: =IF($A6="","",SUMIFS(Recipes!$H$5:$H$104,Recipes!$C$5:$C$104,$A6,Recipes!$B$5:$B$104,"B")) -> 22 | I6: =IF($A6="","",SUMIFS(Recipes!$H$5:$H$104,Recipes!$C$5:$C$104,$A6,Recipes!$B$5:$B$104,"C")) -> 0 | J6: =IF($A6="","",SUMIFS(Movements!$D$5:$D$304,Movements!$C$5:$C$304,$A6,Movements!$B$5:$B$304,"Adjust")) -> 0 | K6: =IF($A6="","",$E6+$F6-$G6-$H6-$I6+$J6) -> 38
A7: BOX-SM | B7: Small Gift Box | C7: Box | D7: 50 | E7: 200 | F7: =IF($A7="","",SUMIFS(Movements!$D$5:$D$304,Movements!$C$5:$C$304,$A7,Movements!$B$5:$B$304,"Receive")) -> 0 | G7: =IF($A7="","",SUMIFS(Movements!$D$5:$D$304,Movements!$C$5:$C$304,$A7,Movements!$B$5:$B$304,"Sell")) -> 0 | H7: =IF($A7="","",SUMIFS(Recipes!$H$5:$H$104,Recipes!$C$5:$C$104,$A7,Recipes!$B$5:$B$104,"B")) -> 22 | I7: =IF($A7="","",SUMIFS(Recipes!$H$5:$H$104,Recipes!$C$5:$C$104,$A7,Recipes!$B$5:$B$104,"C")) -> 0 | J7: =IF($A7="","",SUMIFS(Movements!$D$5:$D$304,Movements!$C$5:$C$304,$A7,Movements!$B$5:$B$304,"Adjust")) -> 0 | K7: =IF($A7="","",$E7+$F7-$G7-$H7-$I7+$J7) -> 178
A8: BANNER-HB | B8: Happy Birthday Banner | C8: Pcs | E8: 150 | F8: =IF($A8="","",SUMIFS(Movements!$D$5:$D$304,Movements!$C$5:$C$304,$A8,Movements!$B$5:$B$304,"Receive")) -> 0 | G8: =IF($A8="","",SUMIFS(Movements!$D$5:$D$304,Movements!$C$5:$C$304,$A8,Movements!$B$5:$B$304,"Sell")) -> 0 | H8: =IF($A8="","",SUMIFS(Recipes!$H$5:$H$104,Recipes!$C$5:$C$104,$A8,Recipes!$B$5:$B$104,"B")) -> 12 | I8: =IF($A8="","",SUMIFS(Recipes!$H$5:$H$104,Recipes!$C$5:$C$104,$A8,Recipes!$B$5:$B$104,"C")) -> 0 | J8: =IF($A8="","",SUMIFS(Movements!$D$5:$D$304,Movements!$C$5:$C$304,$A8,Movements!$B$5:$B$304,"Adjust")) -> 0 | K8: =IF($A8="","",$E8+$F8-$G8-$H8-$I8+$J8) -> 138
A9: PUMP | B9: Hand Pump | C9: Pcs | E9: 80 | F9: =IF($A9="","",SUMIFS(Movements!$D$5:$D$304,Movements!$C$5:$C$304,$A9,Movements!$B$5:$B$304,"Receive")) -> 0 | G9: =IF($A9="","",SUMIFS(Movements!$D$5:$D$304,Movements!$C$5:$C$304,$A9,Movements!$B$5:$B$304,"Sell")) -> 0 | H9: =IF($A9="","",SUMIFS(Recipes!$H$5:$H$104,Recipes!$C$5:$C$104,$A9,Recipes!$B$5:$B$104,"B")) -> 17 | I9: =IF($A9="","",SUMIFS(Recipes!$H$5:$H$104,Recipes!$C$5:$C$104,$A9,Recipes!$B$5:$B$104,"C")) -> 0 | J9: =IF($A9="","",SUMIFS(Movements!$D$5:$D$304,Movements!$C$5:$C$304,$A9,Movements!$B$5:$B$304,"Adjust")) -> 0 | K9: =IF($A9="","",$E9+$F9-$G9-$H9-$I9+$J9) -> 63
F10: =IF($A10="","",SUMIFS(Movements!$D$5:$D$304,Movements!$C$5:$C$304,$A10,Movements!$B$5:$B$304,"Receive")) | G10: =IF($A10="","",SUMIFS(Movements!$D$5:$D$304,Movements!$C$5:$C$304,$A10,Movements!$B$5:$B$304,"Sell")) | H10: =IF($A10="","",SUMIFS(Recipes!$H$5:$H$104,Recipes!$C$5:$C$104,$A10,Recipes!$B$5:$B$104,"B")) | I10: =IF($A10="","",SUMIFS(Recipes!$H$5:$H$104,Recipes!$C$5:$C$104,$A10,Recipes!$B$5:$B$104,"C")) | J10: =IF($A10="","",SUMIFS(Movements!$D$5:$D$304,Movements!$C$5:$C$304,$A10,Movements!$B$5:$B$304,"Adjust")) | K10: =IF($A10="","",$E10+$F10-$G10-$H10-$I10+$J10)
F11: =IF($A11="","",SUMIFS(Movements!$D$5:$D$304,Movements!$C$5:$C$304,$A11,Movements!$B$5:$B$304,"Receive")) | G11: =IF($A11="","",SUMIFS(Movements!$D$5:$D$304,Movements!$C$5:$C$304,$A11,Movements!$B$5:$B$304,"Sell")) | H11: =IF($A11="","",SUMIFS(Recipes!$H$5:$H$104,Recipes!$C$5:$C$104,$A11,Recipes!$B$5:$B$104,"B")) | I11: =IF($A11="","",SUMIFS(Recipes!$H$5:$H$104,Recipes!$C$5:$C$104,$A11,Recipes!$B$5:$B$104,"C")) | J11: =IF($A11="","",SUMIFS(Movements!$D$5:$D$304,Movements!$C$5:$C$304,$A11,Movements!$B$5:$B$304,"Adjust")) | K11: =IF($A11="","",$E11+$F11-$G11-$H11-$I11+$J11)
F12: =IF($A12="","",SUMIFS(Movements!$D$5:$D$304,Movements!$C$5:$C$304,$A12,Movements!$B$5:$B$304,"Receive")) | G12: =IF($A12="","",SUMIFS(Movements!$D$5:$D$304,Movements!$C$5:$C$304,$A12,Movements!$B$5:$B$304,"Sell")) | H12: =IF($A12="","",SUMIFS(Recipes!$H$5:$H$104,Recipes!$C$5:$C$104,$A12,Recipes!$B$5:$B$104,"B")) | I12: =IF($A12="","",SUMIFS(Recipes!$H$5:$H$104,Recipes!$C$5:$C$104,$A12,Recipes!$B$5:$B$104,"C")) | J12: =IF($A12="","",SUMIFS(Movements!$D$5:$D$304,Movements!$C$5:$C$304,$A12,Movements!$B$5:$B$304,"Adjust")) | K12: =IF($A12="","",$E12+$F12-$G12-$H12-$I12+$J12)
F13: =IF($A13="","",SUMIFS(Movements!$D$5:$D$304,Movements!$C$5:$C$304,$A13,Movements!$B$5:$B$304,"Receive")) | G13: =IF($A13="","",SUMIFS(Movements!$D$5:$D$304,Movements!$C$5:$C$304,$A13,Movements!$B$5:$B$304,"Sell")) | H13: =IF($A13="","",SUMIFS(Recipes!$H$5:$H$104,Recipes!$C$5:$C$104,$A13,Recipes!$B$5:$B$104,"B")) | I13: =IF($A13="","",SUMIFS(Recipes!$H$5:$H$104,Recipes!$C$5:$C$104,$A13,Recipes!$B$5:$B$104,"C")) | J13: =IF($A13="","",SUMIFS(Movements!$D$5:$D$304,Movements!$C$5:$C$304,$A13,Movements!$B$5:$B$304,"Adjust")) | K13: =IF($A13="","",$E13+$F13-$G13-$H13-$I13+$J13)
F14: =IF($A14="","",SUMIFS(Movements!$D$5:$D$304,Movements!$C$5:$C$304,$A14,Movements!$B$5:$B$304,"Receive")) | G14: =IF($A14="","",SUMIFS(Movements!$D$5:$D$304,Movements!$C$5:$C$304,$A14,Movements!$B$5:$B$304,"Sell")) | H14: =IF($A14="","",SUMIFS(Recipes!$H$5:$H$104,Recipes!$C$5:$C$104,$A14,Recipes!$B$5:$B$104,"B")) | I14: =IF($A14="","",SUMIFS(Recipes!$H$5:$H$104,Recipes!$C$5:$C$104,$A14,Recipes!$B$5:$B$104,"C")) | J14: =IF($A14="","",SUMIFS(Movements!$D$5:$D$304,Movements!$C$5:$C$304,$A14,Movements!$B$5:$B$304,"Adjust")) | K14: =IF($A14="","",$E14+$F14-$G14-$H14-$I14+$J14)
F15: =IF($A15="","",SUMIFS(Movements!$D$5:$D$304,Movements!$C$5:$C$304,$A15,Movements!$B$5:$B$304,"Receive")) | G15: =IF($A15="","",SUMIFS(Movements!$D$5:$D$304,Movements!$C$5:$C$304,$A15,Movements!$B$5:$B$304,"Sell")) | H15: =IF($A15="","",SUMIFS(Recipes!$H$5:$H$104,Recipes!$C$5:$C$104,$A15,Recipes!$B$5:$B$104,"B")) | I15: =IF($A15="","",SUMIFS(Recipes!$H$5:$H$104,Recipes!$C$5:$C$104,$A15,Recipes!$B$5:$B$104,"C")) | J15: =IF($A15="","",SUMIFS(Movements!$D$5:$D$304,Movements!$C$5:$C$304,$A15,Movements!$B$5:$B$304,"Adjust")) | K15: =IF($A15="","",$E15+$F15-$G15-$H15-$I15+$J15)
F16: =IF($A16="","",SUMIFS(Movements!$D$5:$D$304,Movements!$C$5:$C$304,$A16,Movements!$B$5:$B$304,"Receive")) | G16: =IF($A16="","",SUMIFS(Movements!$D$5:$D$304,Movements!$C$5:$C$304,$A16,Movements!$B$5:$B$304,"Sell")) | H16: =IF($A16="","",SUMIFS(Recipes!$H$5:$H$104,Recipes!$C$5:$C$104,$A16,Recipes!$B$5:$B$104,"B")) | I16: =IF($A16="","",SUMIFS(Recipes!$H$5:$H$104,Recipes!$C$5:$C$104,$A16,Recipes!$B$5:$B$104,"C")) | J16: =IF($A16="","",SUMIFS(Movements!$D$5:$D$304,Movements!$C$5:$C$304,$A16,Movements!$B$5:$B$304,"Adjust")) | K16: =IF($A16="","",$E16+$F16-$G16-$H16-$I16+$J16)
F17: =IF($A17="","",SUMIFS(Movements!$D$5:$D$304,Movements!$C$5:$C$304,$A17,Movements!$B$5:$B$304,"Receive")) | G17: =IF($A17="","",SUMIFS(Movements!$D$5:$D$304,Movements!$C$5:$C$304,$A17,Movements!$B$5:$B$304,"Sell")) | H17: =IF($A17="","",SUMIFS(Recipes!$H$5:$H$104,Recipes!$C$5:$C$104,$A17,Recipes!$B$5:$B$104,"B")) | I17: =IF($A17="","",SUMIFS(Recipes!$H$5:$H$104,Recipes!$C$5:$C$104,$A17,Recipes!$B$5:$B$104,"C")) | J17: =IF($A17="","",SUMIFS(Movements!$D$5:$D$304,Movements!$C$5:$C$304,$A17,Movements!$B$5:$B$304,"Adjust")) | K17: =IF($A17="","",$E17+$F17-$G17-$H17-$I17+$J17)
F18: =IF($A18="","",SUMIFS(Movements!$D$5:$D$304,Movements!$C$5:$C$304,$A18,Movements!$B$5:$B$304,"Receive")) | G18: =IF($A18="","",SUMIFS(Movements!$D$5:$D$304,Movements!$C$5:$C$304,$A18,Movements!$B$5:$B$304,"Sell")) | H18: =IF($A18="","",SUMIFS(Recipes!$H$5:$H$104,Recipes!$C$5:$C$104,$A18,Recipes!$B$5:$B$104,"B")) | I18: =IF($A18="","",SUMIFS(Recipes!$H$5:$H$104,Recipes!$C$5:$C$104,$A18,Recipes!$B$5:$B$104,"C")) | J18: =IF($A18="","",SUMIFS(Movements!$D$5:$D$304,Movements!$C$5:$C$304,$A18,Movements!$B$5:$B$304,"Adjust")) | K18: =IF($A18="","",$E18+$F18-$G18-$H18-$I18+$J18)
F19: =IF($A19="","",SUMIFS(Movements!$D$5:$D$304,Movements!$C$5:$C$304,$A19,Movements!$B$5:$B$304,"Receive")) | G19: =IF($A19="","",SUMIFS(Movements!$D$5:$D$304,Movements!$C$5:$C$304,$A19,Movements!$B$5:$B$304,"Sell")) | H19: =IF($A19="","",SUMIFS(Recipes!$H$5:$H$104,Recipes!$C$5:$C$104,$A19,Recipes!$B$5:$B$104,"B")) | I19: =IF($A19="","",SUMIFS(Recipes!$H$5:$H$104,Recipes!$C$5:$C$104,$A19,Recipes!$B$5:$B$104,"C")) | J19: =IF($A19="","",SUMIFS(Movements!$D$5:$D$304,Movements!$C$5:$C$304,$A19,Movements!$B$5:$B$304,"Adjust")) | K19: =IF($A19="","",$E19+$F19-$G19-$H19-$I19+$J19)
F20: =IF($A20="","",SUMIFS(Movements!$D$5:$D$304,Movements!$C$5:$C$304,$A20,Movements!$B$5:$B$304,"Receive")) | G20: =IF($A20="","",SUMIFS(Movements!$D$5:$D$304,Movements!$C$5:$C$304,$A20,Movements!$B$5:$B$304,"Sell")) | H20: =IF($A20="","",SUMIFS(Recipes!$H$5:$H$104,Recipes!$C$5:$C$104,$A20,Recipes!$B$5:$B$104,"B")) | I20: =IF($A20="","",SUMIFS(Recipes!$H$5:$H$104,Recipes!$C$5:$C$104,$A20,Recipes!$B$5:$B$104,"C")) | J20: =IF($A20="","",SUMIFS(Movements!$D$5:$D$304,Movements!$C$5:$C$304,$A20,Movements!$B$5:$B$304,"Adjust")) | K20: =IF($A20="","",$E20+$F20-$G20-$H20-$I20+$J20)
F21: =IF($A21="","",SUMIFS(Movements!$D$5:$D$304,Movements!$C$5:$C$304,$A21,Movements!$B$5:$B$304,"Receive")) | G21: =IF($A21="","",SUMIFS(Movements!$D$5:$D$304,Movements!$C$5:$C$304,$A21,Movements!$B$5:$B$304,"Sell")) | H21: =IF($A21="","",SUMIFS(Recipes!$H$5:$H$104,Recipes!$C$5:$C$104,$A21,Recipes!$B$5:$B$104,"B")) | I21: =IF($A21="","",SUMIFS(Recipes!$H$5:$H$104,Recipes!$C$5:$C$104,$A21,Recipes!$B$5:$B$104,"C")) | J21: =IF($A21="","",SUMIFS(Movements!$D$5:$D$304,Movements!$C$5:$C$304,$A21,Movements!$B$5:$B$304,"Adjust")) | K21: =IF($A21="","",$E21+$F21-$G21-$H21-$I21+$J21)
... F104: =IF($A104="","",SUMIFS(Movements!$D$5:$D$304,Movements!$C$5:$C$304,$A104,Movements!$B$5:$B$304,"Receive")) | G104: =IF($A104="","",SUMIFS(Movements!$D$5:$D$304,Movements!$C$5:$C$304,$A104,Movements!$B$5:$B$304,"Sell")) | H104: =IF($A104="","",SUMIFS(Recipes!$H$5:$H$104,Recipes!$C$5:$C$104,$A104,Recipes!$B$5:$B$104,"B")) | I104: =IF($A104="","",SUMIFS(Recipes!$H$5:$H$104,Recipes!$C$5:$C$104,$A104,Recipes!$B$5:$B$104,"C")) | J104: =IF($A104="","",SUMIFS(Movements!$D$5:$D$304,Movements!$C$5:$C$304,$A104,Movements!$B$5:$B$304,"Adjust")) | K104: =IF($A104="","",$E104+$F104-$G104-$H104-$I104+$J104)

Sheet B Made
A1: B — Made Items (assembled from loose items, counted as 1 each)
A2: Type Code and Item Name only. Parts go on the Recipes tab, quantities built go on Movements. ON HAND = made up and sitting there. CAN BUILD FROM A = how many more the loose stock would cover.
A4: Code | B4: Item Name | C4: Built | D4: Adjusted | E4: Needed by Kits | F4: ON HAND | G4: Effective Built | H4: Can Build from A | I4: TOTAL POSSIBLE | J4: Limiting Loose Item | K4: Used by # Kits | L4: Notes
A5: B-BOX-ONE | B5: One Balloon Box | C5: =IF($A5="","",SUMIFS(Movements!$D$5:$D$304,Movements!$C$5:$C$304,$A5,Movements!$B$5:$B$304,"Build")) -> 20 | D5: =IF($A5="","",SUMIFS(Movements!$D$5:$D$304,Movements!$C$5:$C$304,$A5,Movements!$B$5:$B$304,"Adjust")) -> 0 | E5: =IF($A5="","",SUMIFS(Recipes!$H$5:$H$104,Recipes!$C$5:$C$104,$A5,Recipes!$B$5:$B$104,"C")) -> 22 | F5: =IF($A5="","",MAX(0,$C5+$D5-$E5)) -> 0 | G5: =IF($A5="","",MAX($C5,$E5)) -> 22 | H5: =IF($A5="","",_xlfn.MINIFS(Recipes!$I$5:$I$104,Recipes!$A$5:$A$104,$A5,Recipes!$B$5:$B$104,"B")) -> 19 | I5: =IF($A5="","",$F5+$H5) -> 19 | J5: =IF($A5="","",IFERROR(INDEX(Recipes!$C$5:$C$104,MATCH($A5&"|"&$H5,Recipes!$M$5:$M$104,0)),"")) -> WHT-BAL | K5: =IF($A5="","",COUNTIFS(Recipes!$C$5:$C$104,$A5,Recipes!$B$5:$B$104,"C")) -> 2 | L5: EXAMPLE ROWS - delete rows 5-7
A6: B-BANNER | B6: Banner Pack | C6: =IF($A6="","",SUMIFS(Movements!$D$5:$D$304,Movements!$C$5:$C$304,$A6,Movements!$B$5:$B$304,"Build")) -> 0 | D6: =IF($A6="","",SUMIFS(Movements!$D$5:$D$304,Movements!$C$5:$C$304,$A6,Movements!$B$5:$B$304,"Adjust")) -> 0 | E6: =IF($A6="","",SUMIFS(Recipes!$H$5:$H$104,Recipes!$C$5:$C$104,$A6,Recipes!$B$5:$B$104,"C")) -> 12 | F6: =IF($A6="","",MAX(0,$C6+$D6-$E6)) -> 0 | G6: =IF($A6="","",MAX($C6,$E6)) -> 12 | H6: =IF($A6="","",_xlfn.MINIFS(Recipes!$I$5:$I$104,Recipes!$A$5:$A$104,$A6,Recipes!$B$5:$B$104,"B")) -> 58 | I6: =IF($A6="","",$F6+$H6) -> 58 | J6: =IF($A6="","",IFERROR(INDEX(Recipes!$C$5:$C$104,MATCH($A6&"|"&$H6,Recipes!$M$5:$M$104,0)),"")) -> WHT-BAL | K6: =IF($A6="","",COUNTIFS(Recipes!$C$5:$C$104,$A6,Recipes!$B$5:$B$104,"C")) -> 1
A7: B-PUMP | B7: Pump Pack | C7: =IF($A7="","",SUMIFS(Movements!$D$5:$D$304,Movements!$C$5:$C$304,$A7,Movements!$B$5:$B$304,"Build")) -> 0 | D7: =IF($A7="","",SUMIFS(Movements!$D$5:$D$304,Movements!$C$5:$C$304,$A7,Movements!$B$5:$B$304,"Adjust")) -> 0 | E7: =IF($A7="","",SUMIFS(Recipes!$H$5:$H$104,Recipes!$C$5:$C$104,$A7,Recipes!$B$5:$B$104,"C")) -> 17 | F7: =IF($A7="","",MAX(0,$C7+$D7-$E7)) -> 0 | G7: =IF($A7="","",MAX($C7,$E7)) -> 17 | H7: =IF($A7="","",_xlfn.MINIFS(Recipes!$I$5:$I$104,Recipes!$A$5:$A$104,$A7,Recipes!$B$5:$B$104,"B")) -> 63 | I7: =IF($A7="","",$F7+$H7) -> 63 | J7: =IF($A7="","",IFERROR(INDEX(Recipes!$C$5:$C$104,MATCH($A7&"|"&$H7,Recipes!$M$5:$M$104,0)),"")) -> PUMP | K7: =IF($A7="","",COUNTIFS(Recipes!$C$5:$C$104,$A7,Recipes!$B$5:$B$104,"C")) -> 2
C8: =IF($A8="","",SUMIFS(Movements!$D$5:$D$304,Movements!$C$5:$C$304,$A8,Movements!$B$5:$B$304,"Build")) | D8: =IF($A8="","",SUMIFS(Movements!$D$5:$D$304,Movements!$C$5:$C$304,$A8,Movements!$B$5:$B$304,"Adjust")) | E8: =IF($A8="","",SUMIFS(Recipes!$H$5:$H$104,Recipes!$C$5:$C$104,$A8,Recipes!$B$5:$B$104,"C")) | F8: =IF($A8="","",MAX(0,$C8+$D8-$E8)) | G8: =IF($A8="","",MAX($C8,$E8)) | H8: =IF($A8="","",_xlfn.MINIFS(Recipes!$I$5:$I$104,Recipes!$A$5:$A$104,$A8,Recipes!$B$5:$B$104,"B")) | I8: =IF($A8="","",$F8+$H8) | J8: =IF($A8="","",IFERROR(INDEX(Recipes!$C$5:$C$104,MATCH($A8&"|"&$H8,Recipes!$M$5:$M$104,0)),"")) | K8: =IF($A8="","",COUNTIFS(Recipes!$C$5:$C$104,$A8,Recipes!$B$5:$B$104,"C"))
C9: =IF($A9="","",SUMIFS(Movements!$D$5:$D$304,Movements!$C$5:$C$304,$A9,Movements!$B$5:$B$304,"Build")) | D9: =IF($A9="","",SUMIFS(Movements!$D$5:$D$304,Movements!$C$5:$C$304,$A9,Movements!$B$5:$B$304,"Adjust")) | E9: =IF($A9="","",SUMIFS(Recipes!$H$5:$H$104,Recipes!$C$5:$C$104,$A9,Recipes!$B$5:$B$104,"C")) | F9: =IF($A9="","",MAX(0,$C9+$D9-$E9)) | G9: =IF($A9="","",MAX($C9,$E9)) | H9: =IF($A9="","",_xlfn.MINIFS(Recipes!$I$5:$I$104,Recipes!$A$5:$A$104,$A9,Recipes!$B$5:$B$104,"B")) | I9: =IF($A9="","",$F9+$H9) | J9: =IF($A9="","",IFERROR(INDEX(Recipes!$C$5:$C$104,MATCH($A9&"|"&$H9,Recipes!$M$5:$M$104,0)),"")) | K9: =IF($A9="","",COUNTIFS(Recipes!$C$5:$C$104,$A9,Recipes!$B$5:$B$104,"C"))
C10: =IF($A10="","",SUMIFS(Movements!$D$5:$D$304,Movements!$C$5:$C$304,$A10,Movements!$B$5:$B$304,"Build")) | D10: =IF($A10="","",SUMIFS(Movements!$D$5:$D$304,Movements!$C$5:$C$304,$A10,Movements!$B$5:$B$304,"Adjust")) | E10: =IF($A10="","",SUMIFS(Recipes!$H$5:$H$104,Recipes!$C$5:$C$104,$A10,Recipes!$B$5:$B$104,"C")) | F10: =IF($A10="","",MAX(0,$C10+$D10-$E10)) | G10: =IF($A10="","",MAX($C10,$E10)) | H10: =IF($A10="","",_xlfn.MINIFS(Recipes!$I$5:$I$104,Recipes!$A$5:$A$104,$A10,Recipes!$B$5:$B$104,"B")) | I10: =IF($A10="","",$F10+$H10) | J10: =IF($A10="","",IFERROR(INDEX(Recipes!$C$5:$C$104,MATCH($A10&"|"&$H10,Recipes!$M$5:$M$104,0)),"")) | K10: =IF($A10="","",COUNTIFS(Recipes!$C$5:$C$104,$A10,Recipes!$B$5:$B$104,"C"))
C11: =IF($A11="","",SUMIFS(Movements!$D$5:$D$304,Movements!$C$5:$C$304,$A11,Movements!$B$5:$B$304,"Build")) | D11: =IF($A11="","",SUMIFS(Movements!$D$5:$D$304,Movements!$C$5:$C$304,$A11,Movements!$B$5:$B$304,"Adjust")) | E11: =IF($A11="","",SUMIFS(Recipes!$H$5:$H$104,Recipes!$C$5:$C$104,$A11,Recipes!$B$5:$B$104,"C")) | F11: =IF($A11="","",MAX(0,$C11+$D11-$E11)) | G11: =IF($A11="","",MAX($C11,$E11)) | H11: =IF($A11="","",_xlfn.MINIFS(Recipes!$I$5:$I$104,Recipes!$A$5:$A$104,$A11,Recipes!$B$5:$B$104,"B")) | I11: =IF($A11="","",$F11+$H11) | J11: =IF($A11="","",IFERROR(INDEX(Recipes!$C$5:$C$104,MATCH($A11&"|"&$H11,Recipes!$M$5:$M$104,0)),"")) | K11: =IF($A11="","",COUNTIFS(Recipes!$C$5:$C$104,$A11,Recipes!$B$5:$B$104,"C"))
C12: =IF($A12="","",SUMIFS(Movements!$D$5:$D$304,Movements!$C$5:$C$304,$A12,Movements!$B$5:$B$304,"Build")) | D12: =IF($A12="","",SUMIFS(Movements!$D$5:$D$304,Movements!$C$5:$C$304,$A12,Movements!$B$5:$B$304,"Adjust")) | E12: =IF($A12="","",SUMIFS(Recipes!$H$5:$H$104,Recipes!$C$5:$C$104,$A12,Recipes!$B$5:$B$104,"C")) | F12: =IF($A12="","",MAX(0,$C12+$D12-$E12)) | G12: =IF($A12="","",MAX($C12,$E12)) | H12: =IF($A12="","",_xlfn.MINIFS(Recipes!$I$5:$I$104,Recipes!$A$5:$A$104,$A12,Recipes!$B$5:$B$104,"B")) | I12: =IF($A12="","",$F12+$H12) | J12: =IF($A12="","",IFERROR(INDEX(Recipes!$C$5:$C$104,MATCH($A12&"|"&$H12,Recipes!$M$5:$M$104,0)),"")) | K12: =IF($A12="","",COUNTIFS(Recipes!$C$5:$C$104,$A12,Recipes!$B$5:$B$104,"C"))
C13: =IF($A13="","",SUMIFS(Movements!$D$5:$D$304,Movements!$C$5:$C$304,$A13,Movements!$B$5:$B$304,"Build")) | D13: =IF($A13="","",SUMIFS(Movements!$D$5:$D$304,Movements!$C$5:$C$304,$A13,Movements!$B$5:$B$304,"Adjust")) | E13: =IF($A13="","",SUMIFS(Recipes!$H$5:$H$104,Recipes!$C$5:$C$104,$A13,Recipes!$B$5:$B$104,"C")) | F13: =IF($A13="","",MAX(0,$C13+$D13-$E13)) | G13: =IF($A13="","",MAX($C13,$E13)) | H13: =IF($A13="","",_xlfn.MINIFS(Recipes!$I$5:$I$104,Recipes!$A$5:$A$104,$A13,Recipes!$B$5:$B$104,"B")) | I13: =IF($A13="","",$F13+$H13) | J13: =IF($A13="","",IFERROR(INDEX(Recipes!$C$5:$C$104,MATCH($A13&"|"&$H13,Recipes!$M$5:$M$104,0)),"")) | K13: =IF($A13="","",COUNTIFS(Recipes!$C$5:$C$104,$A13,Recipes!$B$5:$B$104,"C"))
C14: =IF($A14="","",SUMIFS(Movements!$D$5:$D$304,Movements!$C$5:$C$304,$A14,Movements!$B$5:$B$304,"Build")) | D14: =IF($A14="","",SUMIFS(Movements!$D$5:$D$304,Movements!$C$5:$C$304,$A14,Movements!$B$5:$B$304,"Adjust")) | E14: =IF($A14="","",SUMIFS(Recipes!$H$5:$H$104,Recipes!$C$5:$C$104,$A14,Recipes!$B$5:$B$104,"C")) | F14: =IF($A14="","",MAX(0,$C14+$D14-$E14)) | G14: =IF($A14="","",MAX($C14,$E14)) | H14: =IF($A14="","",_xlfn.MINIFS(Recipes!$I$5:$I$104,Recipes!$A$5:$A$104,$A14,Recipes!$B$5:$B$104,"B")) | I14: =IF($A14="","",$F14+$H14) | J14: =IF($A14="","",IFERROR(INDEX(Recipes!$C$5:$C$104,MATCH($A14&"|"&$H14,Recipes!$M$5:$M$104,0)),"")) | K14: =IF($A14="","",COUNTIFS(Recipes!$C$5:$C$104,$A14,Recipes!$B$5:$B$104,"C"))
C15: =IF($A15="","",SUMIFS(Movements!$D$5:$D$304,Movements!$C$5:$C$304,$A15,Movements!$B$5:$B$304,"Build")) | D15: =IF($A15="","",SUMIFS(Movements!$D$5:$D$304,Movements!$C$5:$C$304,$A15,Movements!$B$5:$B$304,"Adjust")) | E15: =IF($A15="","",SUMIFS(Recipes!$H$5:$H$104,Recipes!$C$5:$C$104,$A15,Recipes!$B$5:$B$104,"C")) | F15: =IF($A15="","",MAX(0,$C15+$D15-$E15)) | G15: =IF($A15="","",MAX($C15,$E15)) | H15: =IF($A15="","",_xlfn.MINIFS(Recipes!$I$5:$I$104,Recipes!$A$5:$A$104,$A15,Recipes!$B$5:$B$104,"B")) | I15: =IF($A15="","",$F15+$H15) | J15: =IF($A15="","",IFERROR(INDEX(Recipes!$C$5:$C$104,MATCH($A15&"|"&$H15,Recipes!$M$5:$M$104,0)),"")) | K15: =IF($A15="","",COUNTIFS(Recipes!$C$5:$C$104,$A15,Recipes!$B$5:$B$104,"C"))
C16: =IF($A16="","",SUMIFS(Movements!$D$5:$D$304,Movements!$C$5:$C$304,$A16,Movements!$B$5:$B$304,"Build")) | D16: =IF($A16="","",SUMIFS(Movements!$D$5:$D$304,Movements!$C$5:$C$304,$A16,Movements!$B$5:$B$304,"Adjust")) | E16: =IF($A16="","",SUMIFS(Recipes!$H$5:$H$104,Recipes!$C$5:$C$104,$A16,Recipes!$B$5:$B$104,"C")) | F16: =IF($A16="","",MAX(0,$C16+$D16-$E16)) | G16: =IF($A16="","",MAX($C16,$E16)) | H16: =IF($A16="","",_xlfn.MINIFS(Recipes!$I$5:$I$104,Recipes!$A$5:$A$104,$A16,Recipes!$B$5:$B$104,"B")) | I16: =IF($A16="","",$F16+$H16) | J16: =IF($A16="","",IFERROR(INDEX(Recipes!$C$5:$C$104,MATCH($A16&"|"&$H16,Recipes!$M$5:$M$104,0)),"")) | K16: =IF($A16="","",COUNTIFS(Recipes!$C$5:$C$104,$A16,Recipes!$B$5:$B$104,"C"))
C17: =IF($A17="","",SUMIFS(Movements!$D$5:$D$304,Movements!$C$5:$C$304,$A17,Movements!$B$5:$B$304,"Build")) | D17: =IF($A17="","",SUMIFS(Movements!$D$5:$D$304,Movements!$C$5:$C$304,$A17,Movements!$B$5:$B$304,"Adjust")) | E17: =IF($A17="","",SUMIFS(Recipes!$H$5:$H$104,Recipes!$C$5:$C$104,$A17,Recipes!$B$5:$B$104,"C")) | F17: =IF($A17="","",MAX(0,$C17+$D17-$E17)) | G17: =IF($A17="","",MAX($C17,$E17)) | H17: =IF($A17="","",_xlfn.MINIFS(Recipes!$I$5:$I$104,Recipes!$A$5:$A$104,$A17,Recipes!$B$5:$B$104,"B")) | I17: =IF($A17="","",$F17+$H17) | J17: =IF($A17="","",IFERROR(INDEX(Recipes!$C$5:$C$104,MATCH($A17&"|"&$H17,Recipes!$M$5:$M$104,0)),"")) | K17: =IF($A17="","",COUNTIFS(Recipes!$C$5:$C$104,$A17,Recipes!$B$5:$B$104,"C"))
C18: =IF($A18="","",SUMIFS(Movements!$D$5:$D$304,Movements!$C$5:$C$304,$A18,Movements!$B$5:$B$304,"Build")) | D18: =IF($A18="","",SUMIFS(Movements!$D$5:$D$304,Movements!$C$5:$C$304,$A18,Movements!$B$5:$B$304,"Adjust")) | E18: =IF($A18="","",SUMIFS(Recipes!$H$5:$H$104,Recipes!$C$5:$C$104,$A18,Recipes!$B$5:$B$104,"C")) | F18: =IF($A18="","",MAX(0,$C18+$D18-$E18)) | G18: =IF($A18="","",MAX($C18,$E18)) | H18: =IF($A18="","",_xlfn.MINIFS(Recipes!$I$5:$I$104,Recipes!$A$5:$A$104,$A18,Recipes!$B$5:$B$104,"B")) | I18: =IF($A18="","",$F18+$H18) | J18: =IF($A18="","",IFERROR(INDEX(Recipes!$C$5:$C$104,MATCH($A18&"|"&$H18,Recipes!$M$5:$M$104,0)),"")) | K18: =IF($A18="","",COUNTIFS(Recipes!$C$5:$C$104,$A18,Recipes!$B$5:$B$104,"C"))
C19: =IF($A19="","",SUMIFS(Movements!$D$5:$D$304,Movements!$C$5:$C$304,$A19,Movements!$B$5:$B$304,"Build")) | D19: =IF($A19="","",SUMIFS(Movements!$D$5:$D$304,Movements!$C$5:$C$304,$A19,Movements!$B$5:$B$304,"Adjust")) | E19: =IF($A19="","",SUMIFS(Recipes!$H$5:$H$104,Recipes!$C$5:$C$104,$A19,Recipes!$B$5:$B$104,"C")) | F19: =IF($A19="","",MAX(0,$C19+$D19-$E19)) | G19: =IF($A19="","",MAX($C19,$E19)) | H19: =IF($A19="","",_xlfn.MINIFS(Recipes!$I$5:$I$104,Recipes!$A$5:$A$104,$A19,Recipes!$B$5:$B$104,"B")) | I19: =IF($A19="","",$F19+$H19) | J19: =IF($A19="","",IFERROR(INDEX(Recipes!$C$5:$C$104,MATCH($A19&"|"&$H19,Recipes!$M$5:$M$104,0)),"")) | K19: =IF($A19="","",COUNTIFS(Recipes!$C$5:$C$104,$A19,Recipes!$B$5:$B$104,"C"))
... C104: =IF($A104="","",SUMIFS(Movements!$D$5:$D$304,Movements!$C$5:$C$304,$A104,Movements!$B$5:$B$304,"Build")) | D104: =IF($A104="","",SUMIFS(Movements!$D$5:$D$304,Movements!$C$5:$C$304,$A104,Movements!$B$5:$B$304,"Adjust")) | E104: =IF($A104="","",SUMIFS(Recipes!$H$5:$H$104,Recipes!$C$5:$C$104,$A104,Recipes!$B$5:$B$104,"C")) | F104: =IF($A104="","",MAX(0,$C104+$D104-$E104)) | G104: =IF($A104="","",MAX($C104,$E104)) | H104: =IF($A104="","",_xlfn.MINIFS(Recipes!$I$5:$I$104,Recipes!$A$5:$A$104,$A104,Recipes!$B$5:$B$104,"B")) | I104: =IF($A104="","",$F104+$H104) | J104: =IF($A104="","",IFERROR(INDEX(Recipes!$C$5:$C$104,MATCH($A104&"|"&$H104,Recipes!$M$5:$M$104,0)),"")) | K104: =IF($A104="","",COUNTIFS(Recipes!$C$5:$C$104,$A104,Recipes!$B$5:$B$104,"C"))

Sheet C Kits
A1: C — Kits (packed per order from B items)
A2: Type Code, Kit Name, the Marketplace SKU you sell it as, and its Price. A kit can be built from B items, loose A items, or a mix of both. Kits are packed per order so there is no shelf count: CAN PACK NOW is what today's made-up and loose stock covers; CAN PACK IF WE BUILD also counts B items not assembled yet.
A4: Code | B4: Kit Name | C4: Marketplace SKU | D4: Price | E4: Sold | F4: CAN PACK NOW | G4: CAN PACK IF WE BUILD | H4: Limiting B Item | I4: Shared Parts | J4: Notes
A5: C-1ST-BDAY | B5: First Birthday Kit | C5: SK-1STBDAY-KIT | D5: 899 | E5: =IF($A5="","",SUMIFS(Movements!$D$5:$D$304,Movements!$C$5:$C$304,$A5,Movements!$B$5:$B$304,"Sell")) -> 12 | F5: =IF($A5="","",_xlfn.MINIFS(Recipes!$J$5:$J$104,Recipes!$A$5:$A$104,$A5,Recipes!$B$5:$B$104,"C")) -> 0 | G5: =IF($A5="","",_xlfn.MINIFS(Recipes!$K$5:$K$104,Recipes!$A$5:$A$104,$A5,Recipes!$B$5:$B$104,"C")) -> 11 | H5: =IF($A5="","",IFERROR(INDEX(Recipes!$C$5:$C$104,MATCH($A5&"|"&$G5,Recipes!$L$5:$L$104,0)),"")) -> WHT-BAL | I5: =IF($A5="","",IF(_xlfn.MAXIFS(Recipes!$N$5:$N$104,Recipes!$A$5:$A$104,$A5,Recipes!$B$5:$B$104,"C")>1,"Shares parts with other kits","")) -> Shares parts with other kits | J5: EXAMPLE ROWS - delete rows 5-6
A6: C-BOX-DUO | B6: Twin Box Kit | C6: SK-BOXDUO-KIT | D6: 1299 | E6: =IF($A6="","",SUMIFS(Movements!$D$5:$D$304,Movements!$C$5:$C$304,$A6,Movements!$B$5:$B$304,"Sell")) -> 5 | F6: =IF($A6="","",_xlfn.MINIFS(Recipes!$J$5:$J$104,Recipes!$A$5:$A$104,$A6,Recipes!$B$5:$B$104,"C")) -> 0 | G6: =IF($A6="","",_xlfn.MINIFS(Recipes!$K$5:$K$104,Recipes!$A$5:$A$104,$A6,Recipes!$B$5:$B$104,"C")) -> 9 | H6: =IF($A6="","",IFERROR(INDEX(Recipes!$C$5:$C$104,MATCH($A6&"|"&$G6,Recipes!$L$5:$L$104,0)),"")) -> B-BOX-ONE | I6: =IF($A6="","",IF(_xlfn.MAXIFS(Recipes!$N$5:$N$104,Recipes!$A$5:$A$104,$A6,Recipes!$B$5:$B$104,"C")>1,"Shares parts with other kits","")) -> Shares parts with other kits
E7: =IF($A7="","",SUMIFS(Movements!$D$5:$D$304,Movements!$C$5:$C$304,$A7,Movements!$B$5:$B$304,"Sell")) | F7: =IF($A7="","",_xlfn.MINIFS(Recipes!$J$5:$J$104,Recipes!$A$5:$A$104,$A7,Recipes!$B$5:$B$104,"C")) | G7: =IF($A7="","",_xlfn.MINIFS(Recipes!$K$5:$K$104,Recipes!$A$5:$A$104,$A7,Recipes!$B$5:$B$104,"C")) | H7: =IF($A7="","",IFERROR(INDEX(Recipes!$C$5:$C$104,MATCH($A7&"|"&$G7,Recipes!$L$5:$L$104,0)),"")) | I7: =IF($A7="","",IF(_xlfn.MAXIFS(Recipes!$N$5:$N$104,Recipes!$A$5:$A$104,$A7,Recipes!$B$5:$B$104,"C")>1,"Shares parts with other kits",""))
E8: =IF($A8="","",SUMIFS(Movements!$D$5:$D$304,Movements!$C$5:$C$304,$A8,Movements!$B$5:$B$304,"Sell")) | F8: =IF($A8="","",_xlfn.MINIFS(Recipes!$J$5:$J$104,Recipes!$A$5:$A$104,$A8,Recipes!$B$5:$B$104,"C")) | G8: =IF($A8="","",_xlfn.MINIFS(Recipes!$K$5:$K$104,Recipes!$A$5:$A$104,$A8,Recipes!$B$5:$B$104,"C")) | H8: =IF($A8="","",IFERROR(INDEX(Recipes!$C$5:$C$104,MATCH($A8&"|"&$G8,Recipes!$L$5:$L$104,0)),"")) | I8: =IF($A8="","",IF(_xlfn.MAXIFS(Recipes!$N$5:$N$104,Recipes!$A$5:$A$104,$A8,Recipes!$B$5:$B$104,"C")>1,"Shares parts with other kits",""))
E9: =IF($A9="","",SUMIFS(Movements!$D$5:$D$304,Movements!$C$5:$C$304,$A9,Movements!$B$5:$B$304,"Sell")) | F9: =IF($A9="","",_xlfn.MINIFS(Recipes!$J$5:$J$104,Recipes!$A$5:$A$104,$A9,Recipes!$B$5:$B$104,"C")) | G9: =IF($A9="","",_xlfn.MINIFS(Recipes!$K$5:$K$104,Recipes!$A$5:$A$104,$A9,Recipes!$B$5:$B$104,"C")) | H9: =IF($A9="","",IFERROR(INDEX(Recipes!$C$5:$C$104,MATCH($A9&"|"&$G9,Recipes!$L$5:$L$104,0)),"")) | I9: =IF($A9="","",IF(_xlfn.MAXIFS(Recipes!$N$5:$N$104,Recipes!$A$5:$A$104,$A9,Recipes!$B$5:$B$104,"C")>1,"Shares parts with other kits",""))
E10: =IF($A10="","",SUMIFS(Movements!$D$5:$D$304,Movements!$C$5:$C$304,$A10,Movements!$B$5:$B$304,"Sell")) | F10: =IF($A10="","",_xlfn.MINIFS(Recipes!$J$5:$J$104,Recipes!$A$5:$A$104,$A10,Recipes!$B$5:$B$104,"C")) | G10: =IF($A10="","",_xlfn.MINIFS(Recipes!$K$5:$K$104,Recipes!$A$5:$A$104,$A10,Recipes!$B$5:$B$104,"C")) | H10: =IF($A10="","",IFERROR(INDEX(Recipes!$C$5:$C$104,MATCH($A10&"|"&$G10,Recipes!$L$5:$L$104,0)),"")) | I10: =IF($A10="","",IF(_xlfn.MAXIFS(Recipes!$N$5:$N$104,Recipes!$A$5:$A$104,$A10,Recipes!$B$5:$B$104,"C")>1,"Shares parts with other kits",""))
E11: =IF($A11="","",SUMIFS(Movements!$D$5:$D$304,Movements!$C$5:$C$304,$A11,Movements!$B$5:$B$304,"Sell")) | F11: =IF($A11="","",_xlfn.MINIFS(Recipes!$J$5:$J$104,Recipes!$A$5:$A$104,$A11,Recipes!$B$5:$B$104,"C")) | G11: =IF($A11="","",_xlfn.MINIFS(Recipes!$K$5:$K$104,Recipes!$A$5:$A$104,$A11,Recipes!$B$5:$B$104,"C")) | H11: =IF($A11="","",IFERROR(INDEX(Recipes!$C$5:$C$104,MATCH($A11&"|"&$G11,Recipes!$L$5:$L$104,0)),"")) | I11: =IF($A11="","",IF(_xlfn.MAXIFS(Recipes!$N$5:$N$104,Recipes!$A$5:$A$104,$A11,Recipes!$B$5:$B$104,"C")>1,"Shares parts with other kits",""))
E12: =IF($A12="","",SUMIFS(Movements!$D$5:$D$304,Movements!$C$5:$C$304,$A12,Movements!$B$5:$B$304,"Sell")) | F12: =IF($A12="","",_xlfn.MINIFS(Recipes!$J$5:$J$104,Recipes!$A$5:$A$104,$A12,Recipes!$B$5:$B$104,"C")) | G12: =IF($A12="","",_xlfn.MINIFS(Recipes!$K$5:$K$104,Recipes!$A$5:$A$104,$A12,Recipes!$B$5:$B$104,"C")) | H12: =IF($A12="","",IFERROR(INDEX(Recipes!$C$5:$C$104,MATCH($A12&"|"&$G12,Recipes!$L$5:$L$104,0)),"")) | I12: =IF($A12="","",IF(_xlfn.MAXIFS(Recipes!$N$5:$N$104,Recipes!$A$5:$A$104,$A12,Recipes!$B$5:$B$104,"C")>1,"Shares parts with other kits",""))
E13: =IF($A13="","",SUMIFS(Movements!$D$5:$D$304,Movements!$C$5:$C$304,$A13,Movements!$B$5:$B$304,"Sell")) | F13: =IF($A13="","",_xlfn.MINIFS(Recipes!$J$5:$J$104,Recipes!$A$5:$A$104,$A13,Recipes!$B$5:$B$104,"C")) | G13: =IF($A13="","",_xlfn.MINIFS(Recipes!$K$5:$K$104,Recipes!$A$5:$A$104,$A13,Recipes!$B$5:$B$104,"C")) | H13: =IF($A13="","",IFERROR(INDEX(Recipes!$C$5:$C$104,MATCH($A13&"|"&$G13,Recipes!$L$5:$L$104,0)),"")) | I13: =IF($A13="","",IF(_xlfn.MAXIFS(Recipes!$N$5:$N$104,Recipes!$A$5:$A$104,$A13,Recipes!$B$5:$B$104,"C")>1,"Shares parts with other kits",""))
E14: =IF($A14="","",SUMIFS(Movements!$D$5:$D$304,Movements!$C$5:$C$304,$A14,Movements!$B$5:$B$304,"Sell")) | F14: =IF($A14="","",_xlfn.MINIFS(Recipes!$J$5:$J$104,Recipes!$A$5:$A$104,$A14,Recipes!$B$5:$B$104,"C")) | G14: =IF($A14="","",_xlfn.MINIFS(Recipes!$K$5:$K$104,Recipes!$A$5:$A$104,$A14,Recipes!$B$5:$B$104,"C")) | H14: =IF($A14="","",IFERROR(INDEX(Recipes!$C$5:$C$104,MATCH($A14&"|"&$G14,Recipes!$L$5:$L$104,0)),"")) | I14: =IF($A14="","",IF(_xlfn.MAXIFS(Recipes!$N$5:$N$104,Recipes!$A$5:$A$104,$A14,Recipes!$B$5:$B$104,"C")>1,"Shares parts with other kits",""))
E15: =IF($A15="","",SUMIFS(Movements!$D$5:$D$304,Movements!$C$5:$C$304,$A15,Movements!$B$5:$B$304,"Sell")) | F15: =IF($A15="","",_xlfn.MINIFS(Recipes!$J$5:$J$104,Recipes!$A$5:$A$104,$A15,Recipes!$B$5:$B$104,"C")) | G15: =IF($A15="","",_xlfn.MINIFS(Recipes!$K$5:$K$104,Recipes!$A$5:$A$104,$A15,Recipes!$B$5:$B$104,"C")) | H15: =IF($A15="","",IFERROR(INDEX(Recipes!$C$5:$C$104,MATCH($A15&"|"&$G15,Recipes!$L$5:$L$104,0)),"")) | I15: =IF($A15="","",IF(_xlfn.MAXIFS(Recipes!$N$5:$N$104,Recipes!$A$5:$A$104,$A15,Recipes!$B$5:$B$104,"C")>1,"Shares parts with other kits",""))
E16: =IF($A16="","",SUMIFS(Movements!$D$5:$D$304,Movements!$C$5:$C$304,$A16,Movements!$B$5:$B$304,"Sell")) | F16: =IF($A16="","",_xlfn.MINIFS(Recipes!$J$5:$J$104,Recipes!$A$5:$A$104,$A16,Recipes!$B$5:$B$104,"C")) | G16: =IF($A16="","",_xlfn.MINIFS(Recipes!$K$5:$K$104,Recipes!$A$5:$A$104,$A16,Recipes!$B$5:$B$104,"C")) | H16: =IF($A16="","",IFERROR(INDEX(Recipes!$C$5:$C$104,MATCH($A16&"|"&$G16,Recipes!$L$5:$L$104,0)),"")) | I16: =IF($A16="","",IF(_xlfn.MAXIFS(Recipes!$N$5:$N$104,Recipes!$A$5:$A$104,$A16,Recipes!$B$5:$B$104,"C")>1,"Shares parts with other kits",""))
E17: =IF($A17="","",SUMIFS(Movements!$D$5:$D$304,Movements!$C$5:$C$304,$A17,Movements!$B$5:$B$304,"Sell")) | F17: =IF($A17="","",_xlfn.MINIFS(Recipes!$J$5:$J$104,Recipes!$A$5:$A$104,$A17,Recipes!$B$5:$B$104,"C")) | G17: =IF($A17="","",_xlfn.MINIFS(Recipes!$K$5:$K$104,Recipes!$A$5:$A$104,$A17,Recipes!$B$5:$B$104,"C")) | H17: =IF($A17="","",IFERROR(INDEX(Recipes!$C$5:$C$104,MATCH($A17&"|"&$G17,Recipes!$L$5:$L$104,0)),"")) | I17: =IF($A17="","",IF(_xlfn.MAXIFS(Recipes!$N$5:$N$104,Recipes!$A$5:$A$104,$A17,Recipes!$B$5:$B$104,"C")>1,"Shares parts with other kits",""))
E18: =IF($A18="","",SUMIFS(Movements!$D$5:$D$304,Movements!$C$5:$C$304,$A18,Movements!$B$5:$B$304,"Sell")) | F18: =IF($A18="","",_xlfn.MINIFS(Recipes!$J$5:$J$104,Recipes!$A$5:$A$104,$A18,Recipes!$B$5:$B$104,"C")) | G18: =IF($A18="","",_xlfn.MINIFS(Recipes!$K$5:$K$104,Recipes!$A$5:$A$104,$A18,Recipes!$B$5:$B$104,"C")) | H18: =IF($A18="","",IFERROR(INDEX(Recipes!$C$5:$C$104,MATCH($A18&"|"&$G18,Recipes!$L$5:$L$104,0)),"")) | I18: =IF($A18="","",IF(_xlfn.MAXIFS(Recipes!$N$5:$N$104,Recipes!$A$5:$A$104,$A18,Recipes!$B$5:$B$104,"C")>1,"Shares parts with other kits",""))
... E104: =IF($A104="","",SUMIFS(Movements!$D$5:$D$304,Movements!$C$5:$C$304,$A104,Movements!$B$5:$B$304,"Sell")) | F104: =IF($A104="","",_xlfn.MINIFS(Recipes!$J$5:$J$104,Recipes!$A$5:$A$104,$A104,Recipes!$B$5:$B$104,"C")) | G104: =IF($A104="","",_xlfn.MINIFS(Recipes!$K$5:$K$104,Recipes!$A$5:$A$104,$A104,Recipes!$B$5:$B$104,"C")) | H104: =IF($A104="","",IFERROR(INDEX(Recipes!$C$5:$C$104,MATCH($A104&"|"&$G104,Recipes!$L$5:$L$104,0)),"")) | I104: =IF($A104="","",IF(_xlfn.MAXIFS(Recipes!$N$5:$N$104,Recipes!$A$5:$A$104,$A104,Recipes!$B$5:$B$104,"C")>1,"Shares parts with other kits",""))

Sheet Recipes
A1: Recipes — one row per ingredient
A2: One row for every ingredient, so an item can have any number of parts. A B item is built from A codes. A C kit can use B codes, A codes, or both — the Component Type column works out which, so just type the code. The pale columns on the right are working-out; leave them be.
A4: Parent Code | B4: Level | C4: Component Code | D4: Qty per Unit | E4: Component Type | F4: Component Name | G4: Units Made | H4: Total Consumed | I4: Buildable from this part | J4: Packable now from this part | K4: Packable if we build | L4: key C | M4: key B | N4: kits using this part | O4: Kit-wide need for this loose item
A5: B-BOX-ONE | B5: B | C5: WHT-BAL | D5: 30 | E5: =IF($C5="","",IF(ISNUMBER(MATCH($C5,'A Loose'!$A$5:$A$104,0)),"A",IF(ISNUMBER(MATCH($C5,'B Made'!$A$5:$A$104,0)),"B","?? unknown code"))) -> A | F5: =IF($C5="","",IFERROR(IF($E5="A",INDEX('A Loose'!$B$5:$B$104,MATCH($C5,'A Loose'!$A$5:$A$104,0)),IF($E5="B",INDEX('B Made'!$B$5:$B$104,MATCH($C5,'B Made'!$A$5:$A$104,0)),"")),"")) -> White Balloon | G5: =IF($A5="","",IF($B5="B",IFERROR(INDEX('B Made'!$G$5:$G$104,MATCH($A5,'B Made'!$A$5:$A$104,0)),0),IF($B5="C",IFERROR(INDEX('C Kits'!$E$5:$E$104,MATCH($A5,'C Kits'!$A$5:$A$104,0)),0),0))) -> 22 | H5: =IF($A5="","",$D5*$G5) -> 660 | I5: =IF($B5<>"B","",IFERROR(IF($D5=0,0,FLOOR(MAX(0,INDEX('A Loose'!$K$5:$K$104,MATCH($C5,'A Loose'!$A$5:$A$104,0)))/$D5,1)),0)) -> 19 | J5: =IF($B5<>"C","",IFERROR(IF($E5="B",IF($D5=0,0,FLOOR(MAX(0,INDEX('B Made'!$F$5:$F$104,MATCH($C5,'B Made'!$A$5:$A$104,0)))/$D5,1)),IF($O5=0,0,FLOOR(MAX(0,INDEX('A Loose'!$K$5:$K$104,MATCH($C5,'A Loose'!$A$5:$A$104,0)))/$O5,1))),0)) | K5: =IF($B5<>"C","",IFERROR(IF($E5="B",IF($D5=0,0,FLOOR(MAX(0,INDEX('B Made'!$I$5:$I$104,MATCH($C5,'B Made'!$A$5:$A$104,0)))/$D5,1)),IF($O5=0,0,FLOOR(MAX(0,INDEX('A Loose'!$K$5:$K$104,MATCH($C5,'A Loose'!$A$5:$A$104,0)))/$O5,1))),0)) | L5: =IF($B5<>"C","",$A5&"|"&$K5) | M5: =IF($B5<>"B","",$A5&"|"&$I5) -> B-BOX-ONE|19 | N5: =IF($C5="","",COUNTIFS(Recipes!$C$5:$C$104,$C5,Recipes!$B$5:$B$104,"C")) -> 1 | O5: =IF(OR($B5<>"C",$E5<>"A"),"",$D5+SUMPRODUCT((Recipes!$A$5:$A$104=$A5)*(Recipes!$B$5:$B$104="C")*(Recipes!$E$5:$E$104="B")*Recipes!$D$5:$D$104*SUMIFS(Recipes!$D$5:$D$104,Recipes!$A$5:$A$104,Recipes!$C$5:$C$104,Recipes!$B$5:$B$104,"B",Recipes!$C$5:$C$104,$C5)))
A6: B-BOX-ONE | B6: B | C6: GLD-FOIL-1 | D6: 1 | E6: =IF($C6="","",IF(ISNUMBER(MATCH($C6,'A Loose'!$A$5:$A$104,0)),"A",IF(ISNUMBER(MATCH($C6,'B Made'!$A$5:$A$104,0)),"B","?? unknown code"))) -> A | F6: =IF($C6="","",IFERROR(IF($E6="A",INDEX('A Loose'!$B$5:$B$104,MATCH($C6,'A Loose'!$A$5:$A$104,0)),IF($E6="B",INDEX('B Made'!$B$5:$B$104,MATCH($C6,'B Made'!$A$5:$A$104,0)),"")),"")) -> Gold Foil Number 1 | G6: =IF($A6="","",IF($B6="B",IFERROR(INDEX('B Made'!$G$5:$G$104,MATCH($A6,'B Made'!$A$5:$A$104,0)),0),IF($B6="C",IFERROR(INDEX('C Kits'!$E$5:$E$104,MATCH($A6,'C Kits'!$A$5:$A$104,0)),0),0))) -> 22 | H6: =IF($A6="","",$D6*$G6) -> 22 | I6: =IF($B6<>"B","",IFERROR(IF($D6=0,0,FLOOR(MAX(0,INDEX('A Loose'!$K$5:$K$104,MATCH($C6,'A Loose'!$A$5:$A$104,0)))/$D6,1)),0)) -> 38 | J6: =IF($B6<>"C","",IFERROR(IF($E6="B",IF($D6=0,0,FLOOR(MAX(0,INDEX('B Made'!$F$5:$F$104,MATCH($C6,'B Made'!$A$5:$A$104,0)))/$D6,1)),IF($O6=0,0,FLOOR(MAX(0,INDEX('A Loose'!$K$5:$K$104,MATCH($C6,'A Loose'!$A$5:$A$104,0)))/$O6,1))),0)) | K6: =IF($B6<>"C","",IFERROR(IF($E6="B",IF($D6=0,0,FLOOR(MAX(0,INDEX('B Made'!$I$5:$I$104,MATCH($C6,'B Made'!$A$5:$A$104,0)))/$D6,1)),IF($O6=0,0,FLOOR(MAX(0,INDEX('A Loose'!$K$5:$K$104,MATCH($C6,'A Loose'!$A$5:$A$104,0)))/$O6,1))),0)) | L6: =IF($B6<>"C","",$A6&"|"&$K6) | M6: =IF($B6<>"B","",$A6&"|"&$I6) -> B-BOX-ONE|38 | N6: =IF($C6="","",COUNTIFS(Recipes!$C$5:$C$104,$C6,Recipes!$B$5:$B$104,"C")) -> 0 | O6: =IF(OR($B6<>"C",$E6<>"A"),"",$D6+SUMPRODUCT((Recipes!$A$5:$A$104=$A6)*(Recipes!$B$5:$B$104="C")*(Recipes!$E$5:$E$104="B")*Recipes!$D$5:$D$104*SUMIFS(Recipes!$D$5:$D$104,Recipes!$A$5:$A$104,Recipes!$C$5:$C$104,Recipes!$B$5:$B$104,"B",Recipes!$C$5:$C$104,$C6)))
A7: B-BOX-ONE | B7: B | C7: BOX-SM | D7: 1 | E7: =IF($C7="","",IF(ISNUMBER(MATCH($C7,'A Loose'!$A$5:$A$104,0)),"A",IF(ISNUMBER(MATCH($C7,'B Made'!$A$5:$A$104,0)),"B","?? unknown code"))) -> A | F7: =IF($C7="","",IFERROR(IF($E7="A",INDEX('A Loose'!$B$5:$B$104,MATCH($C7,'A Loose'!$A$5:$A$104,0)),IF($E7="B",INDEX('B Made'!$B$5:$B$104,MATCH($C7,'B Made'!$A$5:$A$104,0)),"")),"")) -> Small Gift Box | G7: =IF($A7="","",IF($B7="B",IFERROR(INDEX('B Made'!$G$5:$G$104,MATCH($A7,'B Made'!$A$5:$A$104,0)),0),IF($B7="C",IFERROR(INDEX('C Kits'!$E$5:$E$104,MATCH($A7,'C Kits'!$A$5:$A$104,0)),0),0))) -> 22 | H7: =IF($A7="","",$D7*$G7) -> 22 | I7: =IF($B7<>"B","",IFERROR(IF($D7=0,0,FLOOR(MAX(0,INDEX('A Loose'!$K$5:$K$104,MATCH($C7,'A Loose'!$A$5:$A$104,0)))/$D7,1)),0)) -> 178 | J7: =IF($B7<>"C","",IFERROR(IF($E7="B",IF($D7=0,0,FLOOR(MAX(0,INDEX('B Made'!$F$5:$F$104,MATCH($C7,'B Made'!$A$5:$A$104,0)))/$D7,1)),IF($O7=0,0,FLOOR(MAX(0,INDEX('A Loose'!$K$5:$K$104,MATCH($C7,'A Loose'!$A$5:$A$104,0)))/$O7,1))),0)) | K7: =IF($B7<>"C","",IFERROR(IF($E7="B",IF($D7=0,0,FLOOR(MAX(0,INDEX('B Made'!$I$5:$I$104,MATCH($C7,'B Made'!$A$5:$A$104,0)))/$D7,1)),IF($O7=0,0,FLOOR(MAX(0,INDEX('A Loose'!$K$5:$K$104,MATCH($C7,'A Loose'!$A$5:$A$104,0)))/$O7,1))),0)) | L7: =IF($B7<>"C","",$A7&"|"&$K7) | M7: =IF($B7<>"B","",$A7&"|"&$I7) -> B-BOX-ONE|178 | N7: =IF($C7="","",COUNTIFS(Recipes!$C$5:$C$104,$C7,Recipes!$B$5:$B$104,"C")) -> 0 | O7: =IF(OR($B7<>"C",$E7<>"A"),"",$D7+SUMPRODUCT((Recipes!$A$5:$A$104=$A7)*(Recipes!$B$5:$B$104="C")*(Recipes!$E$5:$E$104="B")*Recipes!$D$5:$D$104*SUMIFS(Recipes!$D$5:$D$104,Recipes!$A$5:$A$104,Recipes!$C$5:$C$104,Recipes!$B$5:$B$104,"B",Recipes!$C$5:$C$104,$C7)))
A8: B-BANNER | B8: B | C8: BANNER-HB | D8: 1 | E8: =IF($C8="","",IF(ISNUMBER(MATCH($C8,'A Loose'!$A$5:$A$104,0)),"A",IF(ISNUMBER(MATCH($C8,'B Made'!$A$5:$A$104,0)),"B","?? unknown code"))) -> A | F8: =IF($C8="","",IFERROR(IF($E8="A",INDEX('A Loose'!$B$5:$B$104,MATCH($C8,'A Loose'!$A$5:$A$104,0)),IF($E8="B",INDEX('B Made'!$B$5:$B$104,MATCH($C8,'B Made'!$A$5:$A$104,0)),"")),"")) -> Happy Birthday Banner | G8: =IF($A8="","",IF($B8="B",IFERROR(INDEX('B Made'!$G$5:$G$104,MATCH($A8,'B Made'!$A$5:$A$104,0)),0),IF($B8="C",IFERROR(INDEX('C Kits'!$E$5:$E$104,MATCH($A8,'C Kits'!$A$5:$A$104,0)),0),0))) -> 12 | H8: =IF($A8="","",$D8*$G8) -> 12 | I8: =IF($B8<>"B","",IFERROR(IF($D8=0,0,FLOOR(MAX(0,INDEX('A Loose'!$K$5:$K$104,MATCH($C8,'A Loose'!$A$5:$A$104,0)))/$D8,1)),0)) -> 138 | J8: =IF($B8<>"C","",IFERROR(IF($E8="B",IF($D8=0,0,FLOOR(MAX(0,INDEX('B Made'!$F$5:$F$104,MATCH($C8,'B Made'!$A$5:$A$104,0)))/$D8,1)),IF($O8=0,0,FLOOR(MAX(0,INDEX('A Loose'!$K$5:$K$104,MATCH($C8,'A Loose'!$A$5:$A$104,0)))/$O8,1))),0)) | K8: =IF($B8<>"C","",IFERROR(IF($E8="B",IF($D8=0,0,FLOOR(MAX(0,INDEX('B Made'!$I$5:$I$104,MATCH($C8,'B Made'!$A$5:$A$104,0)))/$D8,1)),IF($O8=0,0,FLOOR(MAX(0,INDEX('A Loose'!$K$5:$K$104,MATCH($C8,'A Loose'!$A$5:$A$104,0)))/$O8,1))),0)) | L8: =IF($B8<>"C","",$A8&"|"&$K8) | M8: =IF($B8<>"B","",$A8&"|"&$I8) -> B-BANNER|138 | N8: =IF($C8="","",COUNTIFS(Recipes!$C$5:$C$104,$C8,Recipes!$B$5:$B$104,"C")) -> 0 | O8: =IF(OR($B8<>"C",$E8<>"A"),"",$D8+SUMPRODUCT((Recipes!$A$5:$A$104=$A8)*(Recipes!$B$5:$B$104="C")*(Recipes!$E$5:$E$104="B")*Recipes!$D$5:$D$104*SUMIFS(Recipes!$D$5:$D$104,Recipes!$A$5:$A$104,Recipes!$C$5:$C$104,Recipes!$B$5:$B$104,"B",Recipes!$C$5:$C$104,$C8)))
A9: B-BANNER | B9: B | C9: WHT-BAL | D9: 10 | E9: =IF($C9="","",IF(ISNUMBER(MATCH($C9,'A Loose'!$A$5:$A$104,0)),"A",IF(ISNUMBER(MATCH($C9,'B Made'!$A$5:$A$104,0)),"B","?? unknown code"))) -> A | F9: =IF($C9="","",IFERROR(IF($E9="A",INDEX('A Loose'!$B$5:$B$104,MATCH($C9,'A Loose'!$A$5:$A$104,0)),IF($E9="B",INDEX('B Made'!$B$5:$B$104,MATCH($C9,'B Made'!$A$5:$A$104,0)),"")),"")) -> White Balloon | G9: =IF($A9="","",IF($B9="B",IFERROR(INDEX('B Made'!$G$5:$G$104,MATCH($A9,'B Made'!$A$5:$A$104,0)),0),IF($B9="C",IFERROR(INDEX('C Kits'!$E$5:$E$104,MATCH($A9,'C Kits'!$A$5:$A$104,0)),0),0))) -> 12 | H9: =IF($A9="","",$D9*$G9) -> 120 | I9: =IF($B9<>"B","",IFERROR(IF($D9=0,0,FLOOR(MAX(0,INDEX('A Loose'!$K$5:$K$104,MATCH($C9,'A Loose'!$A$5:$A$104,0)))/$D9,1)),0)) -> 58 | J9: =IF($B9<>"C","",IFERROR(IF($E9="B",IF($D9=0,0,FLOOR(MAX(0,INDEX('B Made'!$F$5:$F$104,MATCH($C9,'B Made'!$A$5:$A$104,0)))/$D9,1)),IF($O9=0,0,FLOOR(MAX(0,INDEX('A Loose'!$K$5:$K$104,MATCH($C9,'A Loose'!$A$5:$A$104,0)))/$O9,1))),0)) | K9: =IF($B9<>"C","",IFERROR(IF($E9="B",IF($D9=0,0,FLOOR(MAX(0,INDEX('B Made'!$I$5:$I$104,MATCH($C9,'B Made'!$A$5:$A$104,0)))/$D9,1)),IF($O9=0,0,FLOOR(MAX(0,INDEX('A Loose'!$K$5:$K$104,MATCH($C9,'A Loose'!$A$5:$A$104,0)))/$O9,1))),0)) | L9: =IF($B9<>"C","",$A9&"|"&$K9) | M9: =IF($B9<>"B","",$A9&"|"&$I9) -> B-BANNER|58 | N9: =IF($C9="","",COUNTIFS(Recipes!$C$5:$C$104,$C9,Recipes!$B$5:$B$104,"C")) -> 1 | O9: =IF(OR($B9<>"C",$E9<>"A"),"",$D9+SUMPRODUCT((Recipes!$A$5:$A$104=$A9)*(Recipes!$B$5:$B$104="C")*(Recipes!$E$5:$E$104="B")*Recipes!$D$5:$D$104*SUMIFS(Recipes!$D$5:$D$104,Recipes!$A$5:$A$104,Recipes!$C$5:$C$104,Recipes!$B$5:$B$104,"B",Recipes!$C$5:$C$104,$C9)))
A10: B-PUMP | B10: B | C10: PUMP | D10: 1 | E10: =IF($C10="","",IF(ISNUMBER(MATCH($C10,'A Loose'!$A$5:$A$104,0)),"A",IF(ISNUMBER(MATCH($C10,'B Made'!$A$5:$A$104,0)),"B","?? unknown code"))) -> A | F10: =IF($C10="","",IFERROR(IF($E10="A",INDEX('A Loose'!$B$5:$B$104,MATCH($C10,'A Loose'!$A$5:$A$104,0)),IF($E10="B",INDEX('B Made'!$B$5:$B$104,MATCH($C10,'B Made'!$A$5:$A$104,0)),"")),"")) -> Hand Pump | G10: =IF($A10="","",IF($B10="B",IFERROR(INDEX('B Made'!$G$5:$G$104,MATCH($A10,'B Made'!$A$5:$A$104,0)),0),IF($B10="C",IFERROR(INDEX('C Kits'!$E$5:$E$104,MATCH($A10,'C Kits'!$A$5:$A$104,0)),0),0))) -> 17 | H10: =IF($A10="","",$D10*$G10) -> 17 | I10: =IF($B10<>"B","",IFERROR(IF($D10=0,0,FLOOR(MAX(0,INDEX('A Loose'!$K$5:$K$104,MATCH($C10,'A Loose'!$A$5:$A$104,0)))/$D10,1)),0)) -> 63 | J10: =IF($B10<>"C","",IFERROR(IF($E10="B",IF($D10=0,0,FLOOR(MAX(0,INDEX('B Made'!$F$5:$F$104,MATCH($C10,'B Made'!$A$5:$A$104,0)))/$D10,1)),IF($O10=0,0,FLOOR(MAX(0,INDEX('A Loose'!$K$5:$K$104,MATCH($C10,'A Loose'!$A$5:$A$104,0)))/$O10,1))),0)) | K10: =IF($B10<>"C","",IFERROR(IF($E10="B",IF($D10=0,0,FLOOR(MAX(0,INDEX('B Made'!$I$5:$I$104,MATCH($C10,'B Made'!$A$5:$A$104,0)))/$D10,1)),IF($O10=0,0,FLOOR(MAX(0,INDEX('A Loose'!$K$5:$K$104,MATCH($C10,'A Loose'!$A$5:$A$104,0)))/$O10,1))),0)) | L10: =IF($B10<>"C","",$A10&"|"&$K10) | M10: =IF($B10<>"B","",$A10&"|"&$I10) -> B-PUMP|63 | N10: =IF($C10="","",COUNTIFS(Recipes!$C$5:$C$104,$C10,Recipes!$B$5:$B$104,"C")) -> 0 | O10: =IF(OR($B10<>"C",$E10<>"A"),"",$D10+SUMPRODUCT((Recipes!$A$5:$A$104=$A10)*(Recipes!$B$5:$B$104="C")*(Recipes!$E$5:$E$104="B")*Recipes!$D$5:$D$104*SUMIFS(Recipes!$D$5:$D$104,Recipes!$A$5:$A$104,Recipes!$C$5:$C$104,Recipes!$B$5:$B$104,"B",Recipes!$C$5:$C$104,$C10)))
A11: C-1ST-BDAY | B11: C | C11: B-BOX-ONE | D11: 1 | E11: =IF($C11="","",IF(ISNUMBER(MATCH($C11,'A Loose'!$A$5:$A$104,0)),"A",IF(ISNUMBER(MATCH($C11,'B Made'!$A$5:$A$104,0)),"B","?? unknown code"))) -> B | F11: =IF($C11="","",IFERROR(IF($E11="A",INDEX('A Loose'!$B$5:$B$104,MATCH($C11,'A Loose'!$A$5:$A$104,0)),IF($E11="B",INDEX('B Made'!$B$5:$B$104,MATCH($C11,'B Made'!$A$5:$A$104,0)),"")),"")) -> One Balloon Box | G11: =IF($A11="","",IF($B11="B",IFERROR(INDEX('B Made'!$G$5:$G$104,MATCH($A11,'B Made'!$A$5:$A$104,0)),0),IF($B11="C",IFERROR(INDEX('C Kits'!$E$5:$E$104,MATCH($A11,'C Kits'!$A$5:$A$104,0)),0),0))) -> 12 | H11: =IF($A11="","",$D11*$G11) -> 12 | I11: =IF($B11<>"B","",IFERROR(IF($D11=0,0,FLOOR(MAX(0,INDEX('A Loose'!$K$5:$K$104,MATCH($C11,'A Loose'!$A$5:$A$104,0)))/$D11,1)),0)) | J11: =IF($B11<>"C","",IFERROR(IF($E11="B",IF($D11=0,0,FLOOR(MAX(0,INDEX('B Made'!$F$5:$F$104,MATCH($C11,'B Made'!$A$5:$A$104,0)))/$D11,1)),IF($O11=0,0,FLOOR(MAX(0,INDEX('A Loose'!$K$5:$K$104,MATCH($C11,'A Loose'!$A$5:$A$104,0)))/$O11,1))),0)) -> 0 | K11: =IF($B11<>"C","",IFERROR(IF($E11="B",IF($D11=0,0,FLOOR(MAX(0,INDEX('B Made'!$I$5:$I$104,MATCH($C11,'B Made'!$A$5:$A$104,0)))/$D11,1)),IF($O11=0,0,FLOOR(MAX(0,INDEX('A Loose'!$K$5:$K$104,MATCH($C11,'A Loose'!$A$5:$A$104,0)))/$O11,1))),0)) -> 19 | L11: =IF($B11<>"C","",$A11&"|"&$K11) -> C-1ST-BDAY|19 | M11: =IF($B11<>"B","",$A11&"|"&$I11) | N11: =IF($C11="","",COUNTIFS(Recipes!$C$5:$C$104,$C11,Recipes!$B$5:$B$104,"C")) -> 2 | O11: =IF(OR($B11<>"C",$E11<>"A"),"",$D11+SUMPRODUCT((Recipes!$A$5:$A$104=$A11)*(Recipes!$B$5:$B$104="C")*(Recipes!$E$5:$E$104="B")*Recipes!$D$5:$D$104*SUMIFS(Recipes!$D$5:$D$104,Recipes!$A$5:$A$104,Recipes!$C$5:$C$104,Recipes!$B$5:$B$104,"B",Recipes!$C$5:$C$104,$C11)))
A12: C-1ST-BDAY | B12: C | C12: B-BANNER | D12: 1 | E12: =IF($C12="","",IF(ISNUMBER(MATCH($C12,'A Loose'!$A$5:$A$104,0)),"A",IF(ISNUMBER(MATCH($C12,'B Made'!$A$5:$A$104,0)),"B","?? unknown code"))) -> B | F12: =IF($C12="","",IFERROR(IF($E12="A",INDEX('A Loose'!$B$5:$B$104,MATCH($C12,'A Loose'!$A$5:$A$104,0)),IF($E12="B",INDEX('B Made'!$B$5:$B$104,MATCH($C12,'B Made'!$A$5:$A$104,0)),"")),"")) -> Banner Pack | G12: =IF($A12="","",IF($B12="B",IFERROR(INDEX('B Made'!$G$5:$G$104,MATCH($A12,'B Made'!$A$5:$A$104,0)),0),IF($B12="C",IFERROR(INDEX('C Kits'!$E$5:$E$104,MATCH($A12,'C Kits'!$A$5:$A$104,0)),0),0))) -> 12 | H12: =IF($A12="","",$D12*$G12) -> 12 | I12: =IF($B12<>"B","",IFERROR(IF($D12=0,0,FLOOR(MAX(0,INDEX('A Loose'!$K$5:$K$104,MATCH($C12,'A Loose'!$A$5:$A$104,0)))/$D12,1)),0)) | J12: =IF($B12<>"C","",IFERROR(IF($E12="B",IF($D12=0,0,FLOOR(MAX(0,INDEX('B Made'!$F$5:$F$104,MATCH($C12,'B Made'!$A$5:$A$104,0)))/$D12,1)),IF($O12=0,0,FLOOR(MAX(0,INDEX('A Loose'!$K$5:$K$104,MATCH($C12,'A Loose'!$A$5:$A$104,0)))/$O12,1))),0)) -> 0 | K12: =IF($B12<>"C","",IFERROR(IF($E12="B",IF($D12=0,0,FLOOR(MAX(0,INDEX('B Made'!$I$5:$I$104,MATCH($C12,'B Made'!$A$5:$A$104,0)))/$D12,1)),IF($O12=0,0,FLOOR(MAX(0,INDEX('A Loose'!$K$5:$K$104,MATCH($C12,'A Loose'!$A$5:$A$104,0)))/$O12,1))),0)) -> 58 | L12: =IF($B12<>"C","",$A12&"|"&$K12) -> C-1ST-BDAY|58 | M12: =IF($B12<>"B","",$A12&"|"&$I12) | N12: =IF($C12="","",COUNTIFS(Recipes!$C$5:$C$104,$C12,Recipes!$B$5:$B$104,"C")) -> 1 | O12: =IF(OR($B12<>"C",$E12<>"A"),"",$D12+SUMPRODUCT((Recipes!$A$5:$A$104=$A12)*(Recipes!$B$5:$B$104="C")*(Recipes!$E$5:$E$104="B")*Recipes!$D$5:$D$104*SUMIFS(Recipes!$D$5:$D$104,Recipes!$A$5:$A$104,Recipes!$C$5:$C$104,Recipes!$B$5:$B$104,"B",Recipes!$C$5:$C$104,$C12)))
A13: C-1ST-BDAY | B13: C | C13: B-PUMP | D13: 1 | E13: =IF($C13="","",IF(ISNUMBER(MATCH($C13,'A Loose'!$A$5:$A$104,0)),"A",IF(ISNUMBER(MATCH($C13,'B Made'!$A$5:$A$104,0)),"B","?? unknown code"))) -> B | F13: =IF($C13="","",IFERROR(IF($E13="A",INDEX('A Loose'!$B$5:$B$104,MATCH($C13,'A Loose'!$A$5:$A$104,0)),IF($E13="B",INDEX('B Made'!$B$5:$B$104,MATCH($C13,'B Made'!$A$5:$A$104,0)),"")),"")) -> Pump Pack | G13: =IF($A13="","",IF($B13="B",IFERROR(INDEX('B Made'!$G$5:$G$104,MATCH($A13,'B Made'!$A$5:$A$104,0)),0),IF($B13="C",IFERROR(INDEX('C Kits'!$E$5:$E$104,MATCH($A13,'C Kits'!$A$5:$A$104,0)),0),0))) -> 12 | H13: =IF($A13="","",$D13*$G13) -> 12 | I13: =IF($B13<>"B","",IFERROR(IF($D13=0,0,FLOOR(MAX(0,INDEX('A Loose'!$K$5:$K$104,MATCH($C13,'A Loose'!$A$5:$A$104,0)))/$D13,1)),0)) | J13: =IF($B13<>"C","",IFERROR(IF($E13="B",IF($D13=0,0,FLOOR(MAX(0,INDEX('B Made'!$F$5:$F$104,MATCH($C13,'B Made'!$A$5:$A$104,0)))/$D13,1)),IF($O13=0,0,FLOOR(MAX(0,INDEX('A Loose'!$K$5:$K$104,MATCH($C13,'A Loose'!$A$5:$A$104,0)))/$O13,1))),0)) -> 0 | K13: =IF($B13<>"C","",IFERROR(IF($E13="B",IF($D13=0,0,FLOOR(MAX(0,INDEX('B Made'!$I$5:$I$104,MATCH($C13,'B Made'!$A$5:$A$104,0)))/$D13,1)),IF($O13=0,0,FLOOR(MAX(0,INDEX('A Loose'!$K$5:$K$104,MATCH($C13,'A Loose'!$A$5:$A$104,0)))/$O13,1))),0)) -> 63 | L13: =IF($B13<>"C","",$A13&"|"&$K13) -> C-1ST-BDAY|63 | M13: =IF($B13<>"B","",$A13&"|"&$I13) | N13: =IF($C13="","",COUNTIFS(Recipes!$C$5:$C$104,$C13,Recipes!$B$5:$B$104,"C")) -> 2 | O13: =IF(OR($B13<>"C",$E13<>"A"),"",$D13+SUMPRODUCT((Recipes!$A$5:$A$104=$A13)*(Recipes!$B$5:$B$104="C")*(Recipes!$E$5:$E$104="B")*Recipes!$D$5:$D$104*SUMIFS(Recipes!$D$5:$D$104,Recipes!$A$5:$A$104,Recipes!$C$5:$C$104,Recipes!$B$5:$B$104,"B",Recipes!$C$5:$C$104,$C13)))
A14: C-1ST-BDAY | B14: C | C14: WHT-BAL | D14: 10 | E14: =IF($C14="","",IF(ISNUMBER(MATCH($C14,'A Loose'!$A$5:$A$104,0)),"A",IF(ISNUMBER(MATCH($C14,'B Made'!$A$5:$A$104,0)),"B","?? unknown code"))) -> A | F14: =IF($C14="","",IFERROR(IF($E14="A",INDEX('A Loose'!$B$5:$B$104,MATCH($C14,'A Loose'!$A$5:$A$104,0)),IF($E14="B",INDEX('B Made'!$B$5:$B$104,MATCH($C14,'B Made'!$A$5:$A$104,0)),"")),"")) -> White Balloon | G14: =IF($A14="","",IF($B14="B",IFERROR(INDEX('B Made'!$G$5:$G$104,MATCH($A14,'B Made'!$A$5:$A$104,0)),0),IF($B14="C",IFERROR(INDEX('C Kits'!$E$5:$E$104,MATCH($A14,'C Kits'!$A$5:$A$104,0)),0),0))) -> 12 | H14: =IF($A14="","",$D14*$G14) -> 120 | I14: =IF($B14<>"B","",IFERROR(IF($D14=0,0,FLOOR(MAX(0,INDEX('A Loose'!$K$5:$K$104,MATCH($C14,'A Loose'!$A$5:$A$104,0)))/$D14,1)),0)) | J14: =IF($B14<>"C","",IFERROR(IF($E14="B",IF($D14=0,0,FLOOR(MAX(0,INDEX('B Made'!$F$5:$F$104,MATCH($C14,'B Made'!$A$5:$A$104,0)))/$D14,1)),IF($O14=0,0,FLOOR(MAX(0,INDEX('A Loose'!$K$5:$K$104,MATCH($C14,'A Loose'!$A$5:$A$104,0)))/$O14,1))),0)) -> 11 | K14: =IF($B14<>"C","",IFERROR(IF($E14="B",IF($D14=0,0,FLOOR(MAX(0,INDEX('B Made'!$I$5:$I$104,MATCH($C14,'B Made'!$A$5:$A$104,0)))/$D14,1)),IF($O14=0,0,FLOOR(MAX(0,INDEX('A Loose'!$K$5:$K$104,MATCH($C14,'A Loose'!$A$5:$A$104,0)))/$O14,1))),0)) -> 11 | L14: =IF($B14<>"C","",$A14&"|"&$K14) -> C-1ST-BDAY|11 | M14: =IF($B14<>"B","",$A14&"|"&$I14) | N14: =IF($C14="","",COUNTIFS(Recipes!$C$5:$C$104,$C14,Recipes!$B$5:$B$104,"C")) -> 1 | O14: =IF(OR($B14<>"C",$E14<>"A"),"",$D14+SUMPRODUCT((Recipes!$A$5:$A$104=$A14)*(Recipes!$B$5:$B$104="C")*(Recipes!$E$5:$E$104="B")*Recipes!$D$5:$D$104*SUMIFS(Recipes!$D$5:$D$104,Recipes!$A$5:$A$104,Recipes!$C$5:$C$104,Recipes!$B$5:$B$104,"B",Recipes!$C$5:$C$104,$C14))) -> 50
A15: C-BOX-DUO | B15: C | C15: B-BOX-ONE | D15: 2 | E15: =IF($C15="","",IF(ISNUMBER(MATCH($C15,'A Loose'!$A$5:$A$104,0)),"A",IF(ISNUMBER(MATCH($C15,'B Made'!$A$5:$A$104,0)),"B","?? unknown code"))) -> B | F15: =IF($C15="","",IFERROR(IF($E15="A",INDEX('A Loose'!$B$5:$B$104,MATCH($C15,'A Loose'!$A$5:$A$104,0)),IF($E15="B",INDEX('B Made'!$B$5:$B$104,MATCH($C15,'B Made'!$A$5:$A$104,0)),"")),"")) -> One Balloon Box | G15: =IF($A15="","",IF($B15="B",IFERROR(INDEX('B Made'!$G$5:$G$104,MATCH($A15,'B Made'!$A$5:$A$104,0)),0),IF($B15="C",IFERROR(INDEX('C Kits'!$E$5:$E$104,MATCH($A15,'C Kits'!$A$5:$A$104,0)),0),0))) -> 5 | H15: =IF($A15="","",$D15*$G15) -> 10 | I15: =IF($B15<>"B","",IFERROR(IF($D15=0,0,FLOOR(MAX(0,INDEX('A Loose'!$K$5:$K$104,MATCH($C15,'A Loose'!$A$5:$A$104,0)))/$D15,1)),0)) | J15: =IF($B15<>"C","",IFERROR(IF($E15="B",IF($D15=0,0,FLOOR(MAX(0,INDEX('B Made'!$F$5:$F$104,MATCH($C15,'B Made'!$A$5:$A$104,0)))/$D15,1)),IF($O15=0,0,FLOOR(MAX(0,INDEX('A Loose'!$K$5:$K$104,MATCH($C15,'A Loose'!$A$5:$A$104,0)))/$O15,1))),0)) -> 0 | K15: =IF($B15<>"C","",IFERROR(IF($E15="B",IF($D15=0,0,FLOOR(MAX(0,INDEX('B Made'!$I$5:$I$104,MATCH($C15,'B Made'!$A$5:$A$104,0)))/$D15,1)),IF($O15=0,0,FLOOR(MAX(0,INDEX('A Loose'!$K$5:$K$104,MATCH($C15,'A Loose'!$A$5:$A$104,0)))/$O15,1))),0)) -> 9 | L15: =IF($B15<>"C","",$A15&"|"&$K15) -> C-BOX-DUO|9 | M15: =IF($B15<>"B","",$A15&"|"&$I15) | N15: =IF($C15="","",COUNTIFS(Recipes!$C$5:$C$104,$C15,Recipes!$B$5:$B$104,"C")) -> 2 | O15: =IF(OR($B15<>"C",$E15<>"A"),"",$D15+SUMPRODUCT((Recipes!$A$5:$A$104=$A15)*(Recipes!$B$5:$B$104="C")*(Recipes!$E$5:$E$104="B")*Recipes!$D$5:$D$104*SUMIFS(Recipes!$D$5:$D$104,Recipes!$A$5:$A$104,Recipes!$C$5:$C$104,Recipes!$B$5:$B$104,"B",Recipes!$C$5:$C$104,$C15)))
A16: C-BOX-DUO | B16: C | C16: B-PUMP | D16: 1 | E16: =IF($C16="","",IF(ISNUMBER(MATCH($C16,'A Loose'!$A$5:$A$104,0)),"A",IF(ISNUMBER(MATCH($C16,'B Made'!$A$5:$A$104,0)),"B","?? unknown code"))) -> B | F16: =IF($C16="","",IFERROR(IF($E16="A",INDEX('A Loose'!$B$5:$B$104,MATCH($C16,'A Loose'!$A$5:$A$104,0)),IF($E16="B",INDEX('B Made'!$B$5:$B$104,MATCH($C16,'B Made'!$A$5:$A$104,0)),"")),"")) -> Pump Pack | G16: =IF($A16="","",IF($B16="B",IFERROR(INDEX('B Made'!$G$5:$G$104,MATCH($A16,'B Made'!$A$5:$A$104,0)),0),IF($B16="C",IFERROR(INDEX('C Kits'!$E$5:$E$104,MATCH($A16,'C Kits'!$A$5:$A$104,0)),0),0))) -> 5 | H16: =IF($A16="","",$D16*$G16) -> 5 | I16: =IF($B16<>"B","",IFERROR(IF($D16=0,0,FLOOR(MAX(0,INDEX('A Loose'!$K$5:$K$104,MATCH($C16,'A Loose'!$A$5:$A$104,0)))/$D16,1)),0)) | J16: =IF($B16<>"C","",IFERROR(IF($E16="B",IF($D16=0,0,FLOOR(MAX(0,INDEX('B Made'!$F$5:$F$104,MATCH($C16,'B Made'!$A$5:$A$104,0)))/$D16,1)),IF($O16=0,0,FLOOR(MAX(0,INDEX('A Loose'!$K$5:$K$104,MATCH($C16,'A Loose'!$A$5:$A$104,0)))/$O16,1))),0)) -> 0 | K16: =IF($B16<>"C","",IFERROR(IF($E16="B",IF($D16=0,0,FLOOR(MAX(0,INDEX('B Made'!$I$5:$I$104,MATCH($C16,'B Made'!$A$5:$A$104,0)))/$D16,1)),IF($O16=0,0,FLOOR(MAX(0,INDEX('A Loose'!$K$5:$K$104,MATCH($C16,'A Loose'!$A$5:$A$104,0)))/$O16,1))),0)) -> 63 | L16: =IF($B16<>"C","",$A16&"|"&$K16) -> C-BOX-DUO|63 | M16: =IF($B16<>"B","",$A16&"|"&$I16) | N16: =IF($C16="","",COUNTIFS(Recipes!$C$5:$C$104,$C16,Recipes!$B$5:$B$104,"C")) -> 2 | O16: =IF(OR($B16<>"C",$E16<>"A"),"",$D16+SUMPRODUCT((Recipes!$A$5:$A$104=$A16)*(Recipes!$B$5:$B$104="C")*(Recipes!$E$5:$E$104="B")*Recipes!$D$5:$D$104*SUMIFS(Recipes!$D$5:$D$104,Recipes!$A$5:$A$104,Recipes!$C$5:$C$104,Recipes!$B$5:$B$104,"B",Recipes!$C$5:$C$104,$C16)))
E17: =IF($C17="","",IF(ISNUMBER(MATCH($C17,'A Loose'!$A$5:$A$104,0)),"A",IF(ISNUMBER(MATCH($C17,'B Made'!$A$5:$A$104,0)),"B","?? unknown code"))) | F17: =IF($C17="","",IFERROR(IF($E17="A",INDEX('A Loose'!$B$5:$B$104,MATCH($C17,'A Loose'!$A$5:$A$104,0)),IF($E17="B",INDEX('B Made'!$B$5:$B$104,MATCH($C17,'B Made'!$A$5:$A$104,0)),"")),"")) | G17: =IF($A17="","",IF($B17="B",IFERROR(INDEX('B Made'!$G$5:$G$104,MATCH($A17,'B Made'!$A$5:$A$104,0)),0),IF($B17="C",IFERROR(INDEX('C Kits'!$E$5:$E$104,MATCH($A17,'C Kits'!$A$5:$A$104,0)),0),0))) | H17: =IF($A17="","",$D17*$G17) | I17: =IF($B17<>"B","",IFERROR(IF($D17=0,0,FLOOR(MAX(0,INDEX('A Loose'!$K$5:$K$104,MATCH($C17,'A Loose'!$A$5:$A$104,0)))/$D17,1)),0)) | J17: =IF($B17<>"C","",IFERROR(IF($E17="B",IF($D17=0,0,FLOOR(MAX(0,INDEX('B Made'!$F$5:$F$104,MATCH($C17,'B Made'!$A$5:$A$104,0)))/$D17,1)),IF($O17=0,0,FLOOR(MAX(0,INDEX('A Loose'!$K$5:$K$104,MATCH($C17,'A Loose'!$A$5:$A$104,0)))/$O17,1))),0)) | K17: =IF($B17<>"C","",IFERROR(IF($E17="B",IF($D17=0,0,FLOOR(MAX(0,INDEX('B Made'!$I$5:$I$104,MATCH($C17,'B Made'!$A$5:$A$104,0)))/$D17,1)),IF($O17=0,0,FLOOR(MAX(0,INDEX('A Loose'!$K$5:$K$104,MATCH($C17,'A Loose'!$A$5:$A$104,0)))/$O17,1))),0)) | L17: =IF($B17<>"C","",$A17&"|"&$K17) | M17: =IF($B17<>"B","",$A17&"|"&$I17) | N17: =IF($C17="","",COUNTIFS(Recipes!$C$5:$C$104,$C17,Recipes!$B$5:$B$104,"C")) | O17: =IF(OR($B17<>"C",$E17<>"A"),"",$D17+SUMPRODUCT((Recipes!$A$5:$A$104=$A17)*(Recipes!$B$5:$B$104="C")*(Recipes!$E$5:$E$104="B")*Recipes!$D$5:$D$104*SUMIFS(Recipes!$D$5:$D$104,Recipes!$A$5:$A$104,Recipes!$C$5:$C$104,Recipes!$B$5:$B$104,"B",Recipes!$C$5:$C$104,$C17)))
E18: =IF($C18="","",IF(ISNUMBER(MATCH($C18,'A Loose'!$A$5:$A$104,0)),"A",IF(ISNUMBER(MATCH($C18,'B Made'!$A$5:$A$104,0)),"B","?? unknown code"))) | F18: =IF($C18="","",IFERROR(IF($E18="A",INDEX('A Loose'!$B$5:$B$104,MATCH($C18,'A Loose'!$A$5:$A$104,0)),IF($E18="B",INDEX('B Made'!$B$5:$B$104,MATCH($C18,'B Made'!$A$5:$A$104,0)),"")),"")) | G18: =IF($A18="","",IF($B18="B",IFERROR(INDEX('B Made'!$G$5:$G$104,MATCH($A18,'B Made'!$A$5:$A$104,0)),0),IF($B18="C",IFERROR(INDEX('C Kits'!$E$5:$E$104,MATCH($A18,'C Kits'!$A$5:$A$104,0)),0),0))) | H18: =IF($A18="","",$D18*$G18) | I18: =IF($B18<>"B","",IFERROR(IF($D18=0,0,FLOOR(MAX(0,INDEX('A Loose'!$K$5:$K$104,MATCH($C18,'A Loose'!$A$5:$A$104,0)))/$D18,1)),0)) | J18: =IF($B18<>"C","",IFERROR(IF($E18="B",IF($D18=0,0,FLOOR(MAX(0,INDEX('B Made'!$F$5:$F$104,MATCH($C18,'B Made'!$A$5:$A$104,0)))/$D18,1)),IF($O18=0,0,FLOOR(MAX(0,INDEX('A Loose'!$K$5:$K$104,MATCH($C18,'A Loose'!$A$5:$A$104,0)))/$O18,1))),0)) | K18: =IF($B18<>"C","",IFERROR(IF($E18="B",IF($D18=0,0,FLOOR(MAX(0,INDEX('B Made'!$I$5:$I$104,MATCH($C18,'B Made'!$A$5:$A$104,0)))/$D18,1)),IF($O18=0,0,FLOOR(MAX(0,INDEX('A Loose'!$K$5:$K$104,MATCH($C18,'A Loose'!$A$5:$A$104,0)))/$O18,1))),0)) | L18: =IF($B18<>"C","",$A18&"|"&$K18) | M18: =IF($B18<>"B","",$A18&"|"&$I18) | N18: =IF($C18="","",COUNTIFS(Recipes!$C$5:$C$104,$C18,Recipes!$B$5:$B$104,"C")) | O18: =IF(OR($B18<>"C",$E18<>"A"),"",$D18+SUMPRODUCT((Recipes!$A$5:$A$104=$A18)*(Recipes!$B$5:$B$104="C")*(Recipes!$E$5:$E$104="B")*Recipes!$D$5:$D$104*SUMIFS(Recipes!$D$5:$D$104,Recipes!$A$5:$A$104,Recipes!$C$5:$C$104,Recipes!$B$5:$B$104,"B",Recipes!$C$5:$C$104,$C18)))
E19: =IF($C19="","",IF(ISNUMBER(MATCH($C19,'A Loose'!$A$5:$A$104,0)),"A",IF(ISNUMBER(MATCH($C19,'B Made'!$A$5:$A$104,0)),"B","?? unknown code"))) | F19: =IF($C19="","",IFERROR(IF($E19="A",INDEX('A Loose'!$B$5:$B$104,MATCH($C19,'A Loose'!$A$5:$A$104,0)),IF($E19="B",INDEX('B Made'!$B$5:$B$104,MATCH($C19,'B Made'!$A$5:$A$104,0)),"")),"")) | G19: =IF($A19="","",IF($B19="B",IFERROR(INDEX('B Made'!$G$5:$G$104,MATCH($A19,'B Made'!$A$5:$A$104,0)),0),IF($B19="C",IFERROR(INDEX('C Kits'!$E$5:$E$104,MATCH($A19,'C Kits'!$A$5:$A$104,0)),0),0))) | H19: =IF($A19="","",$D19*$G19) | I19: =IF($B19<>"B","",IFERROR(IF($D19=0,0,FLOOR(MAX(0,INDEX('A Loose'!$K$5:$K$104,MATCH($C19,'A Loose'!$A$5:$A$104,0)))/$D19,1)),0)) | J19: =IF($B19<>"C","",IFERROR(IF($E19="B",IF($D19=0,0,FLOOR(MAX(0,INDEX('B Made'!$F$5:$F$104,MATCH($C19,'B Made'!$A$5:$A$104,0)))/$D19,1)),IF($O19=0,0,FLOOR(MAX(0,INDEX('A Loose'!$K$5:$K$104,MATCH($C19,'A Loose'!$A$5:$A$104,0)))/$O19,1))),0)) | K19: =IF($B19<>"C","",IFERROR(IF($E19="B",IF($D19=0,0,FLOOR(MAX(0,INDEX('B Made'!$I$5:$I$104,MATCH($C19,'B Made'!$A$5:$A$104,0)))/$D19,1)),IF($O19=0,0,FLOOR(MAX(0,INDEX('A Loose'!$K$5:$K$104,MATCH($C19,'A Loose'!$A$5:$A$104,0)))/$O19,1))),0)) | L19: =IF($B19<>"C","",$A19&"|"&$K19) | M19: =IF($B19<>"B","",$A19&"|"&$I19) | N19: =IF($C19="","",COUNTIFS(Recipes!$C$5:$C$104,$C19,Recipes!$B$5:$B$104,"C")) | O19: =IF(OR($B19<>"C",$E19<>"A"),"",$D19+SUMPRODUCT((Recipes!$A$5:$A$104=$A19)*(Recipes!$B$5:$B$104="C")*(Recipes!$E$5:$E$104="B")*Recipes!$D$5:$D$104*SUMIFS(Recipes!$D$5:$D$104,Recipes!$A$5:$A$104,Recipes!$C$5:$C$104,Recipes!$B$5:$B$104,"B",Recipes!$C$5:$C$104,$C19)))
